Workbook

Sheet 안내
A1: 토스증권 자동매매 — 신고가 돌파 전략 백테스트 매매내역
A2: 생성일: 2026-09-28 / 기간: 2024-01-01 ~ 2026-09-23 / 생성 스크립트: scripts/make_breakout_report.py
A4: 전략 규칙
A5: 매수: 종가 기준 20일 신고가 (종가 > 직전 20거래일 최고 종가)
A6: + 한 달 내 첫 신고가 (직전 20거래일 동안 20일 신고가가 없었음)
A7: + 당일 거래대금 200억원 이상, 직전 20일 평균 거래대금 30억원 이상
A8: + 종가 10만원 이하, 상한가(+29.5% 이상) 마감 제외, 코스피·코스닥 보통주
A9: → 신고가 날 종가에 매수 (실전: 15:10~15:20). 신호가 많으면 당일 거래대금 큰 순서, 최대 10종목 x 10만원
A10: 매도: 손절 -4.7% (장중 저가가 닿으면 손절가, 갭하락이면 시가) / 익절 +20% (고가가 닿으면 익절가, 갭상승이면 시가)
A11: 같은 날 손절가·익절가 모두 닿으면 손절로 가정 (보수적). 보유기간 제한·시장 필터 없음
A13: 가정
A14: 데이터: FinanceData/marcap (KRX 전 종목 일별, 상장폐지 포함), 무상증자·분할·병합은 KRX 기준가로 수정주가 변환
... A32: 주의: 과거 백테스트 결과이며 미래 수익을 보장하지 않습니다. 일봉 기준이라 장중 체결 순서는 가정입니다.

Sheet 연도별요약
A1: 연도별 요약
A2: 검은 글씨 = 거래내역 시트를 참조하는 수식 / 파란 글씨 = 백테스트 엔진 계산값 (연말 미청산 평가 포함)
A4: 연도 | B4: 매수 | C4: 익절 | D4: 손절 | E4: 보유중 | F4: 승률 | G4: 실현손익(원) | H4: 평균 수익률(청산) | I4: 평균 보유일 | J4: 평균 최고수익률 | K4: 수익률(엔진) | L4: MDD(엔진) | M4: 연말 자산(엔진)
A5: 2024 | B5: =COUNTIFS(거래내역!$A$2:$A$896,2024) -> 334 | C5: =COUNTIFS(거래내역!$A$2:$A$896,2024,거래내역!$L$2:$L$896,"익절") -> 68 | D5: =COUNTIFS(거래내역!$A$2:$A$896,2024,거래내역!$L$2:$L$896,"손절") -> 257 | E5: =COUNTIFS(거래내역!$A$2:$A$896,2024,거래내역!$L$2:$L$896,"보유중") -> 9 | F5: =IFERROR(C5/(C5+D5),0) -> 0.20923077 | G5: =SUMIFS(거래내역!$N$2:$N$896,거래내역!$A$2:$A$896,2024,거래내역!$L$2:$L$896,"<>보유중") -> -24273 | H5: =IFERROR(AVERAGEIFS(거래내역!$O$2:$O$896,거래내역!$A$2:$A$896,2024,거래내역!$L$2:$L$896,"<>보유중"),0) -> 0.00038092592 | I5: =IFERROR(AVERAGEIFS(거래내역!$M$2:$M$896,거래내역!$A$2:$A$896,2024,거래내역!$L$2:$L$896,"<>보유중"),0) -> 6.0769231 | J5: =IFERROR(AVERAGEIFS(거래내역!$P$2:$P$896,거래내역!$A$2:$A$896,2024),0) -> 0.18873148 | K5: -0.004432 | L5: -0.190324 | M5: 995568
A6: 2025 | B6: =COUNTIFS(거래내역!$A$2:$A$896,2025) -> 279 | C6: =COUNTIFS(거래내역!$A$2:$A$896,2025,거래내역!$L$2:$L$896,"익절") -> 77 | D6: =COUNTIFS(거래내역!$A$2:$A$896,2025,거래내역!$L$2:$L$896,"손절") -> 192 | E6: =COUNTIFS(거래내역!$A$2:$A$896,2025,거래내역!$L$2:$L$896,"보유중") -> 10 | F6: =IFERROR(C6/(C6+D6),0) -> 0.28624535 | G6: =SUMIFS(거래내역!$N$2:$N$896,거래내역!$A$2:$A$896,2025,거래내역!$L$2:$L$896,"<>보유중") -> 517185 | H6: =IFERROR(AVERAGEIFS(거래내역!$O$2:$O$896,거래내역!$A$2:$A$896,2025,거래내역!$L$2:$L$896,"<>보유중"),0) -> 0.021339783 | I6: =IFERROR(AVERAGEIFS(거래내역!$M$2:$M$896,거래내역!$A$2:$A$896,2025,거래내역!$L$2:$L$896,"<>보유중"),0) -> 6.8289963 | J6: =IFERROR(AVERAGEIFS(거래내역!$P$2:$P$896,거래내역!$A$2:$A$896,2025),0) -> 0.13510086 | K6: 0.544703 | L6: -0.079692 | M6: 1544703
A7: 2026 | B7: =COUNTIFS(거래내역!$A$2:$A$896,2026) -> 282 | C7: =COUNTIFS(거래내역!$A$2:$A$896,2026,거래내역!$L$2:$L$896,"익절") -> 60 | D7: =COUNTIFS(거래내역!$A$2:$A$896,2026,거래내역!$L$2:$L$896,"손절") -> 212 | E7: =COUNTIFS(거래내역!$A$2:$A$896,2026,거래내역!$L$2:$L$896,"보유중") -> 10 | F7: =IFERROR(C7/(C7+D7),0) -> 0.22058824 | G7: =SUMIFS(거래내역!$N$2:$N$896,거래내역!$A$2:$A$896,2026,거래내역!$L$2:$L$896,"<>보유중") -> 48187 | H7: =IFERROR(AVERAGEIFS(거래내역!$O$2:$O$896,거래내역!$A$2:$A$896,2026,거래내역!$L$2:$L$896,"<>보유중"),0) -> 0.002079852 | I7: =IFERROR(AVERAGEIFS(거래내역!$M$2:$M$896,거래내역!$A$2:$A$896,2026,거래내역!$L$2:$L$896,"<>보유중"),0) -> 3.7316176 | J7: =IFERROR(AVERAGEIFS(거래내역!$P$2:$P$896,거래내역!$A$2:$A$896,2026),0) -> 0.094548384 | K7: 0.074987 | L7: -0.229714 | M7: 1074987
A8: 합계 | B8: =SUM(B5:B7) -> 895 | C8: =SUM(C5:C7) -> 205 | D8: =SUM(D5:D7) -> 661 | E8: =SUM(E5:E7) -> 29 | F8: =IFERROR(C8/(C8+D8),0) -> 0.23672055 | G8: =SUM(G5:G7) -> 541099 | H8: =IFERROR(AVERAGEIFS(거래내역!$O$2:$O$896,거래내역!$L$2:$L$896,"<>보유중"),0) -> 0.0074248525 | I8: =IFERROR(AVERAGEIFS(거래내역!$M$2:$M$896,거래내역!$L$2:$L$896,"<>보유중"),0) -> 5.573903 | J8: =IFERROR(AVERAGE(거래내역!$P$2:$P$896),0) -> 0.14233754 | K8: =SUM(K5:K7) -> 0.615258
A10: 승률 = 익절 / (익절 + 손절). 손익·수익률은 수수료 0.015%, 매도세(2024 0.18%·2025 0.15%·2026 0.20% 가정), 슬리피지 0.1% 반영. 보유중 종목은 기간 말 종가 기준 평가손익.

Sheet 월별
A1: 월별 성과 (청산된 거래 기준, 매수월로 집계)
A3: 매수월 | B3: 매수 | C3: 익절 | D3: 손절 | E3: 보유중 | F3: 승률 | G3: 실현손익(원) | H3: 평균 수익률 | I3: 누적 손익(원)
A4: 2024-01 | B4: =COUNTIFS(거래내역!$B$2:$B$896,A4) -> 48 | C4: =COUNTIFS(거래내역!$B$2:$B$896,A4,거래내역!$L$2:$L$896,"익절") -> 14 | D4: =COUNTIFS(거래내역!$B$2:$B$896,A4,거래내역!$L$2:$L$896,"손절") -> 34 | E4: =COUNTIFS(거래내역!$B$2:$B$896,A4,거래내역!$L$2:$L$896,"보유중") -> 0 | F4: =IFERROR(C4/(C4+D4),0) -> 0.29166667 | G4: =SUMIFS(거래내역!$N$2:$N$896,거래내역!$B$2:$B$896,A4,거래내역!$L$2:$L$896,"<>보유중") -> 85513 | H4: =IFERROR(AVERAGEIFS(거래내역!$O$2:$O$896,거래내역!$B$2:$B$896,A4,거래내역!$L$2:$L$896,"<>보유중"),0) -> 0.021015572 | I4: =G4 -> 85513
A5: 2024-02 | B5: =COUNTIFS(거래내역!$B$2:$B$896,A5) -> 22 | C5: =COUNTIFS(거래내역!$B$2:$B$896,A5,거래내역!$L$2:$L$896,"익절") -> 6 | D5: =COUNTIFS(거래내역!$B$2:$B$896,A5,거래내역!$L$2:$L$896,"손절") -> 16 | E5: =COUNTIFS(거래내역!$B$2:$B$896,A5,거래내역!$L$2:$L$896,"보유중") -> 0 | F5: =IFERROR(C5/(C5+D5),0) -> 0.27272727 | G5: =SUMIFS(거래내역!$N$2:$N$896,거래내역!$B$2:$B$896,A5,거래내역!$L$2:$L$896,"<>보유중") -> 13065 | H5: =IFERROR(AVERAGEIFS(거래내역!$O$2:$O$896,거래내역!$B$2:$B$896,A5,거래내역!$L$2:$L$896,"<>보유중"),0) -> 0.017305577 | I5: =I4+G5 -> 98578
A6: 2024-03 | B6: =COUNTIFS(거래내역!$B$2:$B$896,A6) -> 32 | C6: =COUNTIFS(거래내역!$B$2:$B$896,A6,거래내역!$L$2:$L$896,"익절") -> 9 | D6: =COUNTIFS(거래내역!$B$2:$B$896,A6,거래내역!$L$2:$L$896,"손절") -> 23 | E6: =COUNTIFS(거래내역!$B$2:$B$896,A6,거래내역!$L$2:$L$896,"보유중") -> 0 | F6: =IFERROR(C6/(C6+D6),0) -> 0.28125 | G6: =SUMIFS(거래내역!$N$2:$N$896,거래내역!$B$2:$B$896,A6,거래내역!$L$2:$L$896,"<>보유중") -> 46413 | H6: =IFERROR(AVERAGEIFS(거래내역!$O$2:$O$896,거래내역!$B$2:$B$896,A6,거래내역!$L$2:$L$896,"<>보유중"),0) -> 0.018769982 | I6: =I5+G6 -> 144991
A7: 2024-04 | B7: =COUNTIFS(거래내역!$B$2:$B$896,A7) -> 34 | C7: =COUNTIFS(거래내역!$B$2:$B$896,A7,거래내역!$L$2:$L$896,"익절") -> 2 | D7: =COUNTIFS(거래내역!$B$2:$B$896,A7,거래내역!$L$2:$L$896,"손절") -> 32 | E7: =COUNTIFS(거래내역!$B$2:$B$896,A7,거래내역!$L$2:$L$896,"보유중") -> 0 | F7: =IFERROR(C7/(C7+D7),0) -> 0.058823529 | G7: =SUMIFS(거래내역!$N$2:$N$896,거래내역!$B$2:$B$896,A7,거래내역!$L$2:$L$896,"<>보유중") -> -105883 | H7: =IFERROR(AVERAGEIFS(거래내역!$O$2:$O$896,거래내역!$B$2:$B$896,A7,거래내역!$L$2:$L$896,"<>보유중"),0) -> -0.0362695 | I7: =I6+G7 -> 39108
A8: 2024-05 | B8: =COUNTIFS(거래내역!$B$2:$B$896,A8) -> 19 | C8: =COUNTIFS(거래내역!$B$2:$B$896,A8,거래내역!$L$2:$L$896,"익절") -> 5 | D8: =COUNTIFS(거래내역!$B$2:$B$896,A8,거래내역!$L$2:$L$896,"손절") -> 14 | E8: =COUNTIFS(거래내역!$B$2:$B$896,A8,거래내역!$L$2:$L$896,"보유중") -> 0 | F8: =IFERROR(C8/(C8+D8),0) -> 0.26315789 | G8: =SUMIFS(거래내역!$N$2:$N$896,거래내역!$B$2:$B$896,A8,거래내역!$L$2:$L$896,"<>보유중") -> 20028 | H8: =IFERROR(AVERAGEIFS(거래내역!$O$2:$O$896,거래내역!$B$2:$B$896,A8,거래내역!$L$2:$L$896,"<>보유중"),0) -> 0.014267841 | I8: =I7+G8 -> 59136
A9: 2024-06 | B9: =COUNTIFS(거래내역!$B$2:$B$896,A9) -> 23 | C9: =COUNTIFS(거래내역!$B$2:$B$896,A9,거래내역!$L$2:$L$896,"익절") -> 4 | D9: =COUNTIFS(거래내역!$B$2:$B$896,A9,거래내역!$L$2:$L$896,"손절") -> 18 | E9: =COUNTIFS(거래내역!$B$2:$B$896,A9,거래내역!$L$2:$L$896,"보유중") -> 1 | F9: =IFERROR(C9/(C9+D9),0) -> 0.18181818 | G9: =SUMIFS(거래내역!$N$2:$N$896,거래내역!$B$2:$B$896,A9,거래내역!$L$2:$L$896,"<>보유중") -> -7476 | H9: =IFERROR(AVERAGEIFS(거래내역!$O$2:$O$896,거래내역!$B$2:$B$896,A9,거래내역!$L$2:$L$896,"<>보유중"),0) -> -0.0061464934 | I9: =I8+G9 -> 51660
A10: 2024-07 | B10: =COUNTIFS(거래내역!$B$2:$B$896,A10) -> 18 | C10: =COUNTIFS(거래내역!$B$2:$B$896,A10,거래내역!$L$2:$L$896,"익절") -> 3 | D10: =COUNTIFS(거래내역!$B$2:$B$896,A10,거래내역!$L$2:$L$896,"손절") -> 15 | E10: =COUNTIFS(거래내역!$B$2:$B$896,A10,거래내역!$L$2:$L$896,"보유중") -> 0 | F10: =IFERROR(C10/(C10+D10),0) -> 0.16666667 | G10: =SUMIFS(거래내역!$N$2:$N$896,거래내역!$B$2:$B$896,A10,거래내역!$L$2:$L$896,"<>보유중") -> -18201 | H10: =IFERROR(AVERAGEIFS(거래내역!$O$2:$O$896,거래내역!$B$2:$B$896,A10,거래내역!$L$2:$L$896,"<>보유중"),0) -> -0.010937016 | I10: =I9+G10 -> 33459
A11: 2024-08 | B11: =COUNTIFS(거래내역!$B$2:$B$896,A11) -> 24 | C11: =COUNTIFS(거래내역!$B$2:$B$896,A11,거래내역!$L$2:$L$896,"익절") -> 5 | D11: =COUNTIFS(거래내역!$B$2:$B$896,A11,거래내역!$L$2:$L$896,"손절") -> 19 | E11: =COUNTIFS(거래내역!$B$2:$B$896,A11,거래내역!$L$2:$L$896,"보유중") -> 0 | F11: =IFERROR(C11/(C11+D11),0) -> 0.20833333 | G11: =SUMIFS(거래내역!$N$2:$N$896,거래내역!$B$2:$B$896,A11,거래내역!$L$2:$L$896,"<>보유중") -> -2293 | H11: =IFERROR(AVERAGEIFS(거래내역!$O$2:$O$896,거래내역!$B$2:$B$896,A11,거래내역!$L$2:$L$896,"<>보유중"),0) -> -0.00097185061 | I11: =I10+G11 -> 31166
A12: 2024-09 | B12: =COUNTIFS(거래내역!$B$2:$B$896,A12) -> 20 | C12: =COUNTIFS(거래내역!$B$2:$B$896,A12,거래내역!$L$2:$L$896,"익절") -> 2 | D12: =COUNTIFS(거래내역!$B$2:$B$896,A12,거래내역!$L$2:$L$896,"손절") -> 18 | E12: =COUNTIFS(거래내역!$B$2:$B$896,A12,거래내역!$L$2:$L$896,"보유중") -> 0 | F12: =IFERROR(C12/(C12+D12),0) -> 0.1 | G12: =SUMIFS(거래내역!$N$2:$N$896,거래내역!$B$2:$B$896,A12,거래내역!$L$2:$L$896,"<>보유중") -> -42390 | H12: =IFERROR(AVERAGEIFS(거래내역!$O$2:$O$896,거래내역!$B$2:$B$896,A12,거래내역!$L$2:$L$896,"<>보유중"),0) -> -0.026260093 | I12: =I11+G12 -> -11224
A13: 2024-10 | B13: =COUNTIFS(거래내역!$B$2:$B$896,A13) -> 27 | C13: =COUNTIFS(거래내역!$B$2:$B$896,A13,거래내역!$L$2:$L$896,"익절") -> 5 | D13: =COUNTIFS(거래내역!$B$2:$B$896,A13,거래내역!$L$2:$L$896,"손절") -> 22 | E13: =COUNTIFS(거래내역!$B$2:$B$896,A13,거래내역!$L$2:$L$896,"보유중") -> 0 | F13: =IFERROR(C13/(C13+D13),0) -> 0.18518519 | G13: =SUMIFS(거래내역!$N$2:$N$896,거래내역!$B$2:$B$896,A13,거래내역!$L$2:$L$896,"<>보유중") -> -15496 | H13: =IFERROR(AVERAGEIFS(거래내역!$O$2:$O$896,거래내역!$B$2:$B$896,A13,거래내역!$L$2:$L$896,"<>보유중"),0) -> -0.0048159349 | I13: =I12+G13 -> -26720
A14: 2024-11 | B14: =COUNTIFS(거래내역!$B$2:$B$896,A14) -> 31 | C14: =COUNTIFS(거래내역!$B$2:$B$896,A14,거래내역!$L$2:$L$896,"익절") -> 8 | D14: =COUNTIFS(거래내역!$B$2:$B$896,A14,거래내역!$L$2:$L$896,"손절") -> 23 | E14: =COUNTIFS(거래내역!$B$2:$B$896,A14,거래내역!$L$2:$L$896,"보유중") -> 0 | F14: =IFERROR(C14/(C14+D14),0) -> 0.25806452 | G14: =SUMIFS(거래내역!$N$2:$N$896,거래내역!$B$2:$B$896,A14,거래내역!$L$2:$L$896,"<>보유중") -> 40501 | H14: =IFERROR(AVERAGEIFS(거래내역!$O$2:$O$896,거래내역!$B$2:$B$896,A14,거래내역!$L$2:$L$896,"<>보유중"),0) -> 0.017612514 | I14: =I13+G14 -> 13781
A15: 2024-12 | B15: =COUNTIFS(거래내역!$B$2:$B$896,A15) -> 36 | C15: =COUNTIFS(거래내역!$B$2:$B$896,A15,거래내역!$L$2:$L$896,"익절") -> 5 | D15: =COUNTIFS(거래내역!$B$2:$B$896,A15,거래내역!$L$2:$L$896,"손절") -> 23 | E15: =COUNTIFS(거래내역!$B$2:$B$896,A15,거래내역!$L$2:$L$896,"보유중") -> 8 | F15: =IFERROR(C15/(C15+D15),0) -> 0.17857143 | G15: =SUMIFS(거래내역!$N$2:$N$896,거래내역!$B$2:$B$896,A15,거래내역!$L$2:$L$896,"<>보유중") -> -38054 | H15: =IFERROR(AVERAGEIFS(거래내역!$O$2:$O$896,거래내역!$B$2:$B$896,A15,거래내역!$L$2:$L$896,"<>보유중"),0) -> -0.015699176 | I15: =I14+G15 -> -24273
A16: 2025-01 | B16: =COUNTIFS(거래내역!$B$2:$B$896,A16) -> 29 | C16: =COUNTIFS(거래내역!$B$2:$B$896,A16,거래내역!$L$2:$L$896,"익절") -> 12 | D16: =COUNTIFS(거래내역!$B$2:$B$896,A16,거래내역!$L$2:$L$896,"손절") -> 17 | E16: =COUNTIFS(거래내역!$B$2:$B$896,A16,거래내역!$L$2:$L$896,"보유중") -> 0 | F16: =IFERROR(C16/(C16+D16),0) -> 0.4137931 | G16: =SUMIFS(거래내역!$N$2:$N$896,거래내역!$B$2:$B$896,A16,거래내역!$L$2:$L$896,"<>보유중") -> 141777 | H16: =IFERROR(AVERAGEIFS(거래내역!$O$2:$O$896,거래내역!$B$2:$B$896,A16,거래내역!$L$2:$L$896,"<>보유중"),0) -> 0.052497063 | I16: =I15+G16 -> 117504
... A36: 2026-09 | B36: =COUNTIFS(거래내역!$B$2:$B$896,A36) -> 28 | C36: =COUNTIFS(거래내역!$B$2:$B$896,A36,거래내역!$L$2:$L$896,"익절") -> 6 | D36: =COUNTIFS(거래내역!$B$2:$B$896,A36,거래내역!$L$2:$L$896,"손절") -> 14 | E36: =COUNTIFS(거래내역!$B$2:$B$896,A36,거래내역!$L$2:$L$896,"보유중") -> 8 | F36: =IFERROR(C36/(C36+D36),0) -> 0.3 | G36: =SUMIFS(거래내역!$N$2:$N$896,거래내역!$B$2:$B$896,A36,거래내역!$L$2:$L$896,"<>보유중") -> 38917 | H36: =IFERROR(AVERAGEIFS(거래내역!$O$2:$O$896,거래내역!$B$2:$B$896,A36,거래내역!$L$2:$L$896,"<>보유중"),0) -> 0.024333262 | I36: =I35+G36 -> 541099

Sheet 조건별분석
A1: 조건별 분석 (청산된 거래 기준) — 전략 수정 아이디어 검토용
A2: 연도별 손익이 같은 방향인지 보면 우연인지 판단하는 데 도움이 됩니다. 손익분기 승률은 약 21% (익절 +20% / 손절 -4.7%, 비용 포함).
A4: 매수일 코스피 5일 흐름 (종가가 5거래일 전보다 높으면 상승)
A5: 구분 | B5: 건수 | C5: 익절 | D5: 손절 | E5: 승률 | F5: 손익합(원) | G5: 평균 수익률 | H5: 2024 손익 | I5: 2025 손익 | J5: 2026 손익
A6: 5일 상승 | B6: =COUNTIFS(거래내역!$AB$2:$AB$896,A6,거래내역!$L$2:$L$896,"<>보유중") -> 523 | C6: =COUNTIFS(거래내역!$AB$2:$AB$896,A6,거래내역!$L$2:$L$896,"익절") -> 137 | D6: =COUNTIFS(거래내역!$AB$2:$AB$896,A6,거래내역!$L$2:$L$896,"손절") -> 386 | E6: =IFERROR(C6/(C6+D6),0) -> 0.26195029 | F6: =SUMIFS(거래내역!$N$2:$N$896,거래내역!$AB$2:$AB$896,A6,거래내역!$L$2:$L$896,"<>보유중") -> 548508 | G6: =IFERROR(AVERAGEIFS(거래내역!$O$2:$O$896,거래내역!$AB$2:$AB$896,A6,거래내역!$L$2:$L$896,"<>보유중"),0) -> 0.013576352 | H6: =SUMIFS(거래내역!$N$2:$N$896,거래내역!$AB$2:$AB$896,$A6,거래내역!$L$2:$L$896,"<>보유중",거래내역!$A$2:$A$896,2024) -> -9727 | I6: =SUMIFS(거래내역!$N$2:$N$896,거래내역!$AB$2:$AB$896,$A6,거래내역!$L$2:$L$896,"<>보유중",거래내역!$A$2:$A$896,2025) -> 357260 | J6: =SUMIFS(거래내역!$N$2:$N$896,거래내역!$AB$2:$AB$896,$A6,거래내역!$L$2:$L$896,"<>보유중",거래내역!$A$2:$A$896,2026) -> 200975
A7: 5일 하락 | B7: =COUNTIFS(거래내역!$AB$2:$AB$896,A7,거래내역!$L$2:$L$896,"<>보유중") -> 343 | C7: =COUNTIFS(거래내역!$AB$2:$AB$896,A7,거래내역!$L$2:$L$896,"익절") -> 68 | D7: =COUNTIFS(거래내역!$AB$2:$AB$896,A7,거래내역!$L$2:$L$896,"손절") -> 275 | E7: =IFERROR(C7/(C7+D7),0) -> 0.19825073 | F7: =SUMIFS(거래내역!$N$2:$N$896,거래내역!$AB$2:$AB$896,A7,거래내역!$L$2:$L$896,"<>보유중") -> -7409 | G7: =IFERROR(AVERAGEIFS(거래내역!$O$2:$O$896,거래내역!$AB$2:$AB$896,A7,거래내역!$L$2:$L$896,"<>보유중"),0) -> -0.0019548395 | H7: =SUMIFS(거래내역!$N$2:$N$896,거래내역!$AB$2:$AB$896,$A7,거래내역!$L$2:$L$896,"<>보유중",거래내역!$A$2:$A$896,2024) -> -14546 | I7: =SUMIFS(거래내역!$N$2:$N$896,거래내역!$AB$2:$AB$896,$A7,거래내역!$L$2:$L$896,"<>보유중",거래내역!$A$2:$A$896,2025) -> 159925 | J7: =SUMIFS(거래내역!$N$2:$N$896,거래내역!$AB$2:$AB$896,$A7,거래내역!$L$2:$L$896,"<>보유중",거래내역!$A$2:$A$896,2026) -> -152788
A9: 매수일 코스피 20일선 위치
A10: 구분 | B10: 건수 | C10: 익절 | D10: 손절 | E10: 승률 | F10: 손익합(원) | G10: 평균 수익률 | H10: 2024 손익 | I10: 2025 손익 | J10: 2026 손익
A11: 아래 | B11: =COUNTIFS(거래내역!$AA$2:$AA$896,A11,거래내역!$L$2:$L$896,"<>보유중") -> 335 | C11: =COUNTIFS(거래내역!$AA$2:$AA$896,A11,거래내역!$L$2:$L$896,"익절") -> 73 | D11: =COUNTIFS(거래내역!$AA$2:$AA$896,A11,거래내역!$L$2:$L$896,"손절") -> 262 | E11: =IFERROR(C11/(C11+D11),0) -> 0.21791045 | F11: =SUMIFS(거래내역!$N$2:$N$896,거래내역!$AA$2:$AA$896,A11,거래내역!$L$2:$L$896,"<>보유중") -> 134005 | G11: =IFERROR(AVERAGEIFS(거래내역!$O$2:$O$896,거래내역!$AA$2:$AA$896,A11,거래내역!$L$2:$L$896,"<>보유중"),0) -> 0.003127835 | H11: =SUMIFS(거래내역!$N$2:$N$896,거래내역!$AA$2:$AA$896,$A11,거래내역!$L$2:$L$896,"<>보유중",거래내역!$A$2:$A$896,2024) -> 17644 | I11: =SUMIFS(거래내역!$N$2:$N$896,거래내역!$AA$2:$AA$896,$A11,거래내역!$L$2:$L$896,"<>보유중",거래내역!$A$2:$A$896,2025) -> 207168 | J11: =SUMIFS(거래내역!$N$2:$N$896,거래내역!$AA$2:$AA$896,$A11,거래내역!$L$2:$L$896,"<>보유중",거래내역!$A$2:$A$896,2026) -> -90807
A12: 위 | B12: =COUNTIFS(거래내역!$AA$2:$AA$896,A12,거래내역!$L$2:$L$896,"<>보유중") -> 531 | C12: =COUNTIFS(거래내역!$AA$2:$AA$896,A12,거래내역!$L$2:$L$896,"익절") -> 132 | D12: =COUNTIFS(거래내역!$AA$2:$AA$896,A12,거래내역!$L$2:$L$896,"손절") -> 399 | E12: =IFERROR(C12/(C12+D12),0) -> 0.24858757 | F12: =SUMIFS(거래내역!$N$2:$N$896,거래내역!$AA$2:$AA$896,A12,거래내역!$L$2:$L$896,"<>보유중") -> 407094 | G12: =IFERROR(AVERAGEIFS(거래내역!$O$2:$O$896,거래내역!$AA$2:$AA$896,A12,거래내역!$L$2:$L$896,"<>보유중"),0) -> 0.010135777 | H12: =SUMIFS(거래내역!$N$2:$N$896,거래내역!$AA$2:$AA$896,$A12,거래내역!$L$2:$L$896,"<>보유중",거래내역!$A$2:$A$896,2024) -> -41917 | I12: =SUMIFS(거래내역!$N$2:$N$896,거래내역!$AA$2:$AA$896,$A12,거래내역!$L$2:$L$896,"<>보유중",거래내역!$A$2:$A$896,2025) -> 310017 | J12: =SUMIFS(거래내역!$N$2:$N$896,거래내역!$AA$2:$AA$896,$A12,거래내역!$L$2:$L$896,"<>보유중",거래내역!$A$2:$A$896,2026) -> 138994
A14: 매수일 당일 상승률
A15: 구분 | B15: 건수 | C15: 익절 | D15: 손절 | E15: 승률 | F15: 손익합(원) | G15: 평균 수익률 | H15: 2024 손익 | I15: 2025 손익 | J15: 2026 손익
A16: 1) +3% 미만 | B16: =COUNTIFS(거래내역!$AC$2:$AC$896,A16,거래내역!$L$2:$L$896,"<>보유중") -> 96 | C16: =COUNTIFS(거래내역!$AC$2:$AC$896,A16,거래내역!$L$2:$L$896,"익절") -> 31 | D16: =COUNTIFS(거래내역!$AC$2:$AC$896,A16,거래내역!$L$2:$L$896,"손절") -> 65 | E16: =IFERROR(C16/(C16+D16),0) -> 0.32291667 | F16: =SUMIFS(거래내역!$N$2:$N$896,거래내역!$AC$2:$AC$896,A16,거래내역!$L$2:$L$896,"<>보유중") -> 213936 | G16: =IFERROR(AVERAGEIFS(거래내역!$O$2:$O$896,거래내역!$AC$2:$AC$896,A16,거래내역!$L$2:$L$896,"<>보유중"),0) -> 0.029724654 | H16: =SUMIFS(거래내역!$N$2:$N$896,거래내역!$AC$2:$AC$896,$A16,거래내역!$L$2:$L$896,"<>보유중",거래내역!$A$2:$A$896,2024) -> 23453 | I16: =SUMIFS(거래내역!$N$2:$N$896,거래내역!$AC$2:$AC$896,$A16,거래내역!$L$2:$L$896,"<>보유중",거래내역!$A$2:$A$896,2025) -> 97937 | J16: =SUMIFS(거래내역!$N$2:$N$896,거래내역!$AC$2:$AC$896,$A16,거래내역!$L$2:$L$896,"<>보유중",거래내역!$A$2:$A$896,2026) -> 92546
A17: 2) +3% ~ +5% | B17: =COUNTIFS(거래내역!$AC$2:$AC$896,A17,거래내역!$L$2:$L$896,"<>보유중") -> 0 | C17: =COUNTIFS(거래내역!$AC$2:$AC$896,A17,거래내역!$L$2:$L$896,"익절") -> 0 | D17: =COUNTIFS(거래내역!$AC$2:$AC$896,A17,거래내역!$L$2:$L$896,"손절") -> 0 | E17: =IFERROR(C17/(C17+D17),0) -> 0 | F17: =SUMIFS(거래내역!$N$2:$N$896,거래내역!$AC$2:$AC$896,A17,거래내역!$L$2:$L$896,"<>보유중") -> 0 | G17: =IFERROR(AVERAGEIFS(거래내역!$O$2:$O$896,거래내역!$AC$2:$AC$896,A17,거래내역!$L$2:$L$896,"<>보유중"),0) -> 0 | H17: =SUMIFS(거래내역!$N$2:$N$896,거래내역!$AC$2:$AC$896,$A17,거래내역!$L$2:$L$896,"<>보유중",거래내역!$A$2:$A$896,2024) -> 0 | I17: =SUMIFS(거래내역!$N$2:$N$896,거래내역!$AC$2:$AC$896,$A17,거래내역!$L$2:$L$896,"<>보유중",거래내역!$A$2:$A$896,2025) -> 0 | J17: =SUMIFS(거래내역!$N$2:$N$896,거래내역!$AC$2:$AC$896,$A17,거래내역!$L$2:$L$896,"<>보유중",거래내역!$A$2:$A$896,2026) -> 0
A18: 3) +5% ~ +10% | B18: =COUNTIFS(거래내역!$AC$2:$AC$896,A18,거래내역!$L$2:$L$896,"<>보유중") -> 0 | C18: =COUNTIFS(거래내역!$AC$2:$AC$896,A18,거래내역!$L$2:$L$896,"익절") -> 0 | D18: =COUNTIFS(거래내역!$AC$2:$AC$896,A18,거래내역!$L$2:$L$896,"손절") -> 0 | E18: =IFERROR(C18/(C18+D18),0) -> 0 | F18: =SUMIFS(거래내역!$N$2:$N$896,거래내역!$AC$2:$AC$896,A18,거래내역!$L$2:$L$896,"<>보유중") -> 0 | G18: =IFERROR(AVERAGEIFS(거래내역!$O$2:$O$896,거래내역!$AC$2:$AC$896,A18,거래내역!$L$2:$L$896,"<>보유중"),0) -> 0 | H18: =SUMIFS(거래내역!$N$2:$N$896,거래내역!$AC$2:$AC$896,$A18,거래내역!$L$2:$L$896,"<>보유중",거래내역!$A$2:$A$896,2024) -> 0 | I18: =SUMIFS(거래내역!$N$2:$N$896,거래내역!$AC$2:$AC$896,$A18,거래내역!$L$2:$L$896,"<>보유중",거래내역!$A$2:$A$896,2025) -> 0 | J18: =SUMIFS(거래내역!$N$2:$N$896,거래내역!$AC$2:$AC$896,$A18,거래내역!$L$2:$L$896,"<>보유중",거래내역!$A$2:$A$896,2026) -> 0
A19: 4) +10% ~ +15% | B19: =COUNTIFS(거래내역!$AC$2:$AC$896,A19,거래내역!$L$2:$L$896,"<>보유중") -> 0 | C19: =COUNTIFS(거래내역!$AC$2:$AC$896,A19,거래내역!$L$2:$L$896,"익절") -> 0 | D19: =COUNTIFS(거래내역!$AC$2:$AC$896,A19,거래내역!$L$2:$L$896,"손절") -> 0 | E19: =IFERROR(C19/(C19+D19),0) -> 0 | F19: =SUMIFS(거래내역!$N$2:$N$896,거래내역!$AC$2:$AC$896,A19,거래내역!$L$2:$L$896,"<>보유중") -> 0 | G19: =IFERROR(AVERAGEIFS(거래내역!$O$2:$O$896,거래내역!$AC$2:$AC$896,A19,거래내역!$L$2:$L$896,"<>보유중"),0) -> 0 | H19: =SUMIFS(거래내역!$N$2:$N$896,거래내역!$AC$2:$AC$896,$A19,거래내역!$L$2:$L$896,"<>보유중",거래내역!$A$2:$A$896,2024) -> 0 | I19: =SUMIFS(거래내역!$N$2:$N$896,거래내역!$AC$2:$AC$896,$A19,거래내역!$L$2:$L$896,"<>보유중",거래내역!$A$2:$A$896,2025) -> 0 | J19: =SUMIFS(거래내역!$N$2:$N$896,거래내역!$AC$2:$AC$896,$A19,거래내역!$L$2:$L$896,"<>보유중",거래내역!$A$2:$A$896,2026) -> 0
A20: 5) +15% ~ +20% | B20: =COUNTIFS(거래내역!$AC$2:$AC$896,A20,거래내역!$L$2:$L$896,"<>보유중") -> 0 | C20: =COUNTIFS(거래내역!$AC$2:$AC$896,A20,거래내역!$L$2:$L$896,"익절") -> 0 | D20: =COUNTIFS(거래내역!$AC$2:$AC$896,A20,거래내역!$L$2:$L$896,"손절") -> 0 | E20: =IFERROR(C20/(C20+D20),0) -> 0 | F20: =SUMIFS(거래내역!$N$2:$N$896,거래내역!$AC$2:$AC$896,A20,거래내역!$L$2:$L$896,"<>보유중") -> 0 | G20: =IFERROR(AVERAGEIFS(거래내역!$O$2:$O$896,거래내역!$AC$2:$AC$896,A20,거래내역!$L$2:$L$896,"<>보유중"),0) -> 0 | H20: =SUMIFS(거래내역!$N$2:$N$896,거래내역!$AC$2:$AC$896,$A20,거래내역!$L$2:$L$896,"<>보유중",거래내역!$A$2:$A$896,2024) -> 0 | I20: =SUMIFS(거래내역!$N$2:$N$896,거래내역!$AC$2:$AC$896,$A20,거래내역!$L$2:$L$896,"<>보유중",거래내역!$A$2:$A$896,2025) -> 0 | J20: =SUMIFS(거래내역!$N$2:$N$896,거래내역!$AC$2:$AC$896,$A20,거래내역!$L$2:$L$896,"<>보유중",거래내역!$A$2:$A$896,2026) -> 0
A21: 6) +20% 이상 | B21: =COUNTIFS(거래내역!$AC$2:$AC$896,A21,거래내역!$L$2:$L$896,"<>보유중") -> 83 | C21: =COUNTIFS(거래내역!$AC$2:$AC$896,A21,거래내역!$L$2:$L$896,"익절") -> 17 | D21: =COUNTIFS(거래내역!$AC$2:$AC$896,A21,거래내역!$L$2:$L$896,"손절") -> 66 | E21: =IFERROR(C21/(C21+D21),0) -> 0.20481928 | F21: =SUMIFS(거래내역!$N$2:$N$896,거래내역!$AC$2:$AC$896,A21,거래내역!$L$2:$L$896,"<>보유중") -> -10542 | G21: =IFERROR(AVERAGEIFS(거래내역!$O$2:$O$896,거래내역!$AC$2:$AC$896,A21,거래내역!$L$2:$L$896,"<>보유중"),0) -> -0.00062463463 | H21: =SUMIFS(거래내역!$N$2:$N$896,거래내역!$AC$2:$AC$896,$A21,거래내역!$L$2:$L$896,"<>보유중",거래내역!$A$2:$A$896,2024) -> -33841 | I21: =SUMIFS(거래내역!$N$2:$N$896,거래내역!$AC$2:$AC$896,$A21,거래내역!$L$2:$L$896,"<>보유중",거래내역!$A$2:$A$896,2025) -> 30418 | J21: =SUMIFS(거래내역!$N$2:$N$896,거래내역!$AC$2:$AC$896,$A21,거래내역!$L$2:$L$896,"<>보유중",거래내역!$A$2:$A$896,2026) -> -7119
A23: 매수일 당일 거래대금
A24: 구분 | B24: 건수 | C24: 익절 | D24: 손절 | E24: 승률 | F24: 손익합(원) | G24: 평균 수익률 | H24: 2024 손익 | I24: 2025 손익 | J24: 2026 손익
A25: 1) 300억 미만 | B25: =COUNTIFS(거래내역!$AD$2:$AD$896,A25,거래내역!$L$2:$L$896,"<>보유중") -> 123 | C25: =COUNTIFS(거래내역!$AD$2:$AD$896,A25,거래내역!$L$2:$L$896,"익절") -> 37 | D25: =COUNTIFS(거래내역!$AD$2:$AD$896,A25,거래내역!$L$2:$L$896,"손절") -> 86 | E25: =IFERROR(C25/(C25+D25),0) -> 0.30081301 | F25: =SUMIFS(거래내역!$N$2:$N$896,거래내역!$AD$2:$AD$896,A25,거래내역!$L$2:$L$896,"<>보유중") -> 250202 | G25: =IFERROR(AVERAGEIFS(거래내역!$O$2:$O$896,거래내역!$AD$2:$AD$896,A25,거래내역!$L$2:$L$896,"<>보유중"),0) -> 0.023060993 | H25: =SUMIFS(거래내역!$N$2:$N$896,거래내역!$AD$2:$AD$896,$A25,거래내역!$L$2:$L$896,"<>보유중",거래내역!$A$2:$A$896,2024) -> 130821 | I25: =SUMIFS(거래내역!$N$2:$N$896,거래내역!$AD$2:$AD$896,$A25,거래내역!$L$2:$L$896,"<>보유중",거래내역!$A$2:$A$896,2025) -> 98321 | J25: =SUMIFS(거래내역!$N$2:$N$896,거래내역!$AD$2:$AD$896,$A25,거래내역!$L$2:$L$896,"<>보유중",거래내역!$A$2:$A$896,2026) -> 21060
A26: 2) 300억 ~ 500억 | B26: =COUNTIFS(거래내역!$AD$2:$AD$896,A26,거래내역!$L$2:$L$896,"<>보유중") -> 0 | C26: =COUNTIFS(거래내역!$AD$2:$AD$896,A26,거래내역!$L$2:$L$896,"익절") -> 0 | D26: =COUNTIFS(거래내역!$AD$2:$AD$896,A26,거래내역!$L$2:$L$896,"손절") -> 0 | E26: =IFERROR(C26/(C26+D26),0) -> 0 | F26: =SUMIFS(거래내역!$N$2:$N$896,거래내역!$AD$2:$AD$896,A26,거래내역!$L$2:$L$896,"<>보유중") -> 0 | G26: =IFERROR(AVERAGEIFS(거래내역!$O$2:$O$896,거래내역!$AD$2:$AD$896,A26,거래내역!$L$2:$L$896,"<>보유중"),0) -> 0 | H26: =SUMIFS(거래내역!$N$2:$N$896,거래내역!$AD$2:$AD$896,$A26,거래내역!$L$2:$L$896,"<>보유중",거래내역!$A$2:$A$896,2024) -> 0 | I26: =SUMIFS(거래내역!$N$2:$N$896,거래내역!$AD$2:$AD$896,$A26,거래내역!$L$2:$L$896,"<>보유중",거래내역!$A$2:$A$896,2025) -> 0 | J26: =SUMIFS(거래내역!$N$2:$N$896,거래내역!$AD$2:$AD$896,$A26,거래내역!$L$2:$L$896,"<>보유중",거래내역!$A$2:$A$896,2026) -> 0
A27: 3) 500억 ~ 1,000억 | B27: =COUNTIFS(거래내역!$AD$2:$AD$896,A27,거래내역!$L$2:$L$896,"<>보유중") -> 0 | C27: =COUNTIFS(거래내역!$AD$2:$AD$896,A27,거래내역!$L$2:$L$896,"익절") -> 0 | D27: =COUNTIFS(거래내역!$AD$2:$AD$896,A27,거래내역!$L$2:$L$896,"손절") -> 0 | E27: =IFERROR(C27/(C27+D27),0) -> 0 | F27: =SUMIFS(거래내역!$N$2:$N$896,거래내역!$AD$2:$AD$896,A27,거래내역!$L$2:$L$896,"<>보유중") -> 0 | G27: =IFERROR(AVERAGEIFS(거래내역!$O$2:$O$896,거래내역!$AD$2:$AD$896,A27,거래내역!$L$2:$L$896,"<>보유중"),0) -> 0 | H27: =SUMIFS(거래내역!$N$2:$N$896,거래내역!$AD$2:$AD$896,$A27,거래내역!$L$2:$L$896,"<>보유중",거래내역!$A$2:$A$896,2024) -> 0 | I27: =SUMIFS(거래내역!$N$2:$N$896,거래내역!$AD$2:$AD$896,$A27,거래내역!$L$2:$L$896,"<>보유중",거래내역!$A$2:$A$896,2025) -> 0 | J27: =SUMIFS(거래내역!$N$2:$N$896,거래내역!$AD$2:$AD$896,$A27,거래내역!$L$2:$L$896,"<>보유중",거래내역!$A$2:$A$896,2026) -> 0
A28: 4) 1,000억 ~ 2,000억 | B28: =COUNTIFS(거래내역!$AD$2:$AD$896,A28,거래내역!$L$2:$L$896,"<>보유중") -> 0 | C28: =COUNTIFS(거래내역!$AD$2:$AD$896,A28,거래내역!$L$2:$L$896,"익절") -> 0 | D28: =COUNTIFS(거래내역!$AD$2:$AD$896,A28,거래내역!$L$2:$L$896,"손절") -> 0 | E28: =IFERROR(C28/(C28+D28),0) -> 0 | F28: =SUMIFS(거래내역!$N$2:$N$896,거래내역!$AD$2:$AD$896,A28,거래내역!$L$2:$L$896,"<>보유중") -> 0 | G28: =IFERROR(AVERAGEIFS(거래내역!$O$2:$O$896,거래내역!$AD$2:$AD$896,A28,거래내역!$L$2:$L$896,"<>보유중"),0) -> 0 | H28: =SUMIFS(거래내역!$N$2:$N$896,거래내역!$AD$2:$AD$896,$A28,거래내역!$L$2:$L$896,"<>보유중",거래내역!$A$2:$A$896,2024) -> 0 | I28: =SUMIFS(거래내역!$N$2:$N$896,거래내역!$AD$2:$AD$896,$A28,거래내역!$L$2:$L$896,"<>보유중",거래내역!$A$2:$A$896,2025) -> 0 | J28: =SUMIFS(거래내역!$N$2:$N$896,거래내역!$AD$2:$AD$896,$A28,거래내역!$L$2:$L$896,"<>보유중",거래내역!$A$2:$A$896,2026) -> 0
A29: 5) 2,000억 이상 | B29: =COUNTIFS(거래내역!$AD$2:$AD$896,A29,거래내역!$L$2:$L$896,"<>보유중") -> 128 | C29: =COUNTIFS(거래내역!$AD$2:$AD$896,A29,거래내역!$L$2:$L$896,"익절") -> 21 | D29: =COUNTIFS(거래내역!$AD$2:$AD$896,A29,거래내역!$L$2:$L$896,"손절") -> 107 | E29: =IFERROR(C29/(C29+D29),0) -> 0.1640625 | F29: =SUMIFS(거래내역!$N$2:$N$896,거래내역!$AD$2:$AD$896,A29,거래내역!$L$2:$L$896,"<>보유중") -> -143346 | G29: =IFERROR(AVERAGEIFS(거래내역!$O$2:$O$896,거래내역!$AD$2:$AD$896,A29,거래내역!$L$2:$L$896,"<>보유중"),0) -> -0.010285494 | H29: =SUMIFS(거래내역!$N$2:$N$896,거래내역!$AD$2:$AD$896,$A29,거래내역!$L$2:$L$896,"<>보유중",거래내역!$A$2:$A$896,2024) -> -32919 | I29: =SUMIFS(거래내역!$N$2:$N$896,거래내역!$AD$2:$AD$896,$A29,거래내역!$L$2:$L$896,"<>보유중",거래내역!$A$2:$A$896,2025) -> -11613 | J29: =SUMIFS(거래내역!$N$2:$N$896,거래내역!$AD$2:$AD$896,$A29,거래내역!$L$2:$L$896,"<>보유중",거래내역!$A$2:$A$896,2026) -> -98814
A31: 20일 신고가 돌파폭 (종가 / 직전 20일 최고 종가)
A32: 구분 | B32: 건수 | C32: 익절 | D32: 손절 | E32: 승률 | F32: 손익합(원) | G32: 평균 수익률 | H32: 2024 손익 | I32: 2025 손익 | J32: 2026 손익
A33: 1) +2% 미만 | B33: =COUNTIFS(거래내역!$AE$2:$AE$896,A33,거래내역!$L$2:$L$896,"<>보유중") -> 246 | C33: =COUNTIFS(거래내역!$AE$2:$AE$896,A33,거래내역!$L$2:$L$896,"익절") -> 70 | D33: =COUNTIFS(거래내역!$AE$2:$AE$896,A33,거래내역!$L$2:$L$896,"손절") -> 176 | E33: =IFERROR(C33/(C33+D33),0) -> 0.28455285 | F33: =SUMIFS(거래내역!$N$2:$N$896,거래내역!$AE$2:$AE$896,A33,거래내역!$L$2:$L$896,"<>보유중") -> 378817 | G33: =IFERROR(AVERAGEIFS(거래내역!$O$2:$O$896,거래내역!$AE$2:$AE$896,A33,거래내역!$L$2:$L$896,"<>보유중"),0) -> 0.018444617 | H33: =SUMIFS(거래내역!$N$2:$N$896,거래내역!$AE$2:$AE$896,$A33,거래내역!$L$2:$L$896,"<>보유중",거래내역!$A$2:$A$896,2024) -> 73163 | I33: =SUMIFS(거래내역!$N$2:$N$896,거래내역!$AE$2:$AE$896,$A33,거래내역!$L$2:$L$896,"<>보유중",거래내역!$A$2:$A$896,2025) -> 170767 | J33: =SUMIFS(거래내역!$N$2:$N$896,거래내역!$AE$2:$AE$896,$A33,거래내역!$L$2:$L$896,"<>보유중",거래내역!$A$2:$A$896,2026) -> 134887
A34: 2) +2% ~ +5% | B34: =COUNTIFS(거래내역!$AE$2:$AE$896,A34,거래내역!$L$2:$L$896,"<>보유중") -> 0 | C34: =COUNTIFS(거래내역!$AE$2:$AE$896,A34,거래내역!$L$2:$L$896,"익절") -> 0 | D34: =COUNTIFS(거래내역!$AE$2:$AE$896,A34,거래내역!$L$2:$L$896,"손절") -> 0 | E34: =IFERROR(C34/(C34+D34),0) -> 0 | F34: =SUMIFS(거래내역!$N$2:$N$896,거래내역!$AE$2:$AE$896,A34,거래내역!$L$2:$L$896,"<>보유중") -> 0 | G34: =IFERROR(AVERAGEIFS(거래내역!$O$2:$O$896,거래내역!$AE$2:$AE$896,A34,거래내역!$L$2:$L$896,"<>보유중"),0) -> 0 | H34: =SUMIFS(거래내역!$N$2:$N$896,거래내역!$AE$2:$AE$896,$A34,거래내역!$L$2:$L$896,"<>보유중",거래내역!$A$2:$A$896,2024) -> 0 | I34: =SUMIFS(거래내역!$N$2:$N$896,거래내역!$AE$2:$AE$896,$A34,거래내역!$L$2:$L$896,"<>보유중",거래내역!$A$2:$A$896,2025) -> 0 | J34: =SUMIFS(거래내역!$N$2:$N$896,거래내역!$AE$2:$AE$896,$A34,거래내역!$L$2:$L$896,"<>보유중",거래내역!$A$2:$A$896,2026) -> 0
A35: 3) +5% ~ +10% | B35: =COUNTIFS(거래내역!$AE$2:$AE$896,A35,거래내역!$L$2:$L$896,"<>보유중") -> 0 | C35: =COUNTIFS(거래내역!$AE$2:$AE$896,A35,거래내역!$L$2:$L$896,"익절") -> 0 | D35: =COUNTIFS(거래내역!$AE$2:$AE$896,A35,거래내역!$L$2:$L$896,"손절") -> 0 | E35: =IFERROR(C35/(C35+D35),0) -> 0 | F35: =SUMIFS(거래내역!$N$2:$N$896,거래내역!$AE$2:$AE$896,A35,거래내역!$L$2:$L$896,"<>보유중") -> 0 | G35: =IFERROR(AVERAGEIFS(거래내역!$O$2:$O$896,거래내역!$AE$2:$AE$896,A35,거래내역!$L$2:$L$896,"<>보유중"),0) -> 0 | H35: =SUMIFS(거래내역!$N$2:$N$896,거래내역!$AE$2:$AE$896,$A35,거래내역!$L$2:$L$896,"<>보유중",거래내역!$A$2:$A$896,2024) -> 0 | I35: =SUMIFS(거래내역!$N$2:$N$896,거래내역!$AE$2:$AE$896,$A35,거래내역!$L$2:$L$896,"<>보유중",거래내역!$A$2:$A$896,2025) -> 0 | J35: =SUMIFS(거래내역!$N$2:$N$896,거래내역!$AE$2:$AE$896,$A35,거래내역!$L$2:$L$896,"<>보유중",거래내역!$A$2:$A$896,2026) -> 0
A36: 4) +10% 이상 | B36: =COUNTIFS(거래내역!$AE$2:$AE$896,A36,거래내역!$L$2:$L$896,"<>보유중") -> 126 | C36: =COUNTIFS(거래내역!$AE$2:$AE$896,A36,거래내역!$L$2:$L$896,"익절") -> 32 | D36: =COUNTIFS(거래내역!$AE$2:$AE$896,A36,거래내역!$L$2:$L$896,"손절") -> 94 | E36: =IFERROR(C36/(C36+D36),0) -> 0.25396825 | F36: =SUMIFS(거래내역!$N$2:$N$896,거래내역!$AE$2:$AE$896,A36,거래내역!$L$2:$L$896,"<>보유중") -> 71874 | G36: =IFERROR(AVERAGEIFS(거래내역!$O$2:$O$896,거래내역!$AE$2:$AE$896,A36,거래내역!$L$2:$L$896,"<>보유중"),0) -> 0.0084951366 | H36: =SUMIFS(거래내역!$N$2:$N$896,거래내역!$AE$2:$AE$896,$A36,거래내역!$L$2:$L$896,"<>보유중",거래내역!$A$2:$A$896,2024) -> -45145 | I36: =SUMIFS(거래내역!$N$2:$N$896,거래내역!$AE$2:$AE$896,$A36,거래내역!$L$2:$L$896,"<>보유중",거래내역!$A$2:$A$896,2025) -> 67327 | J36: =SUMIFS(거래내역!$N$2:$N$896,거래내역!$AE$2:$AE$896,$A36,거래내역!$L$2:$L$896,"<>보유중",거래내역!$A$2:$A$896,2026) -> 49692
A38: 거래량 배수 (당일 / 직전 20일 평균)
A39: 구분 | B39: 건수 | C39: 익절 | D39: 손절 | E39: 승률 | F39: 손익합(원) | G39: 평균 수익률 | H39: 2024 손익 | I39: 2025 손익 | J39: 2026 손익
A40: 1) 2배 미만 | B40: =COUNTIFS(거래내역!$AF$2:$AF$896,A40,거래내역!$L$2:$L$896,"<>보유중") -> 193 | C40: =COUNTIFS(거래내역!$AF$2:$AF$896,A40,거래내역!$L$2:$L$896,"익절") -> 49 | D40: =COUNTIFS(거래내역!$AF$2:$AF$896,A40,거래내역!$L$2:$L$896,"손절") -> 144 | E40: =IFERROR(C40/(C40+D40),0) -> 0.25388601 | F40: =SUMIFS(거래내역!$N$2:$N$896,거래내역!$AF$2:$AF$896,A40,거래내역!$L$2:$L$896,"<>보유중") -> 177952 | G40: =IFERROR(AVERAGEIFS(거래내역!$O$2:$O$896,거래내역!$AF$2:$AF$896,A40,거래내역!$L$2:$L$896,"<>보유중"),0) -> 0.01050917 | H40: =SUMIFS(거래내역!$N$2:$N$896,거래내역!$AF$2:$AF$896,$A40,거래내역!$L$2:$L$896,"<>보유중",거래내역!$A$2:$A$896,2024) -> -5180 | I40: =SUMIFS(거래내역!$N$2:$N$896,거래내역!$AF$2:$AF$896,$A40,거래내역!$L$2:$L$896,"<>보유중",거래내역!$A$2:$A$896,2025) -> 138334 | J40: =SUMIFS(거래내역!$N$2:$N$896,거래내역!$AF$2:$AF$896,$A40,거래내역!$L$2:$L$896,"<>보유중",거래내역!$A$2:$A$896,2026) -> 44798
A41: 2) 2배 ~ 3배 | B41: =COUNTIFS(거래내역!$AF$2:$AF$896,A41,거래내역!$L$2:$L$896,"<>보유중") -> 0 | C41: =COUNTIFS(거래내역!$AF$2:$AF$896,A41,거래내역!$L$2:$L$896,"익절") -> 0 | D41: =COUNTIFS(거래내역!$AF$2:$AF$896,A41,거래내역!$L$2:$L$896,"손절") -> 0 | E41: =IFERROR(C41/(C41+D41),0) -> 0 | F41: =SUMIFS(거래내역!$N$2:$N$896,거래내역!$AF$2:$AF$896,A41,거래내역!$L$2:$L$896,"<>보유중") -> 0 | G41: =IFERROR(AVERAGEIFS(거래내역!$O$2:$O$896,거래내역!$AF$2:$AF$896,A41,거래내역!$L$2:$L$896,"<>보유중"),0) -> 0 | H41: =SUMIFS(거래내역!$N$2:$N$896,거래내역!$AF$2:$AF$896,$A41,거래내역!$L$2:$L$896,"<>보유중",거래내역!$A$2:$A$896,2024) -> 0 | I41: =SUMIFS(거래내역!$N$2:$N$896,거래내역!$AF$2:$AF$896,$A41,거래내역!$L$2:$L$896,"<>보유중",거래내역!$A$2:$A$896,2025) -> 0 | J41: =SUMIFS(거래내역!$N$2:$N$896,거래내역!$AF$2:$AF$896,$A41,거래내역!$L$2:$L$896,"<>보유중",거래내역!$A$2:$A$896,2026) -> 0
A42: 3) 3배 ~ 5배 | B42: =COUNTIFS(거래내역!$AF$2:$AF$896,A42,거래내역!$L$2:$L$896,"<>보유중") -> 0 | C42: =COUNTIFS(거래내역!$AF$2:$AF$896,A42,거래내역!$L$2:$L$896,"익절") -> 0 | D42: =COUNTIFS(거래내역!$AF$2:$AF$896,A42,거래내역!$L$2:$L$896,"손절") -> 0 | E42: =IFERROR(C42/(C42+D42),0) -> 0 | F42: =SUMIFS(거래내역!$N$2:$N$896,거래내역!$AF$2:$AF$896,A42,거래내역!$L$2:$L$896,"<>보유중") -> 0 | G42: =IFERROR(AVERAGEIFS(거래내역!$O$2:$O$896,거래내역!$AF$2:$AF$896,A42,거래내역!$L$2:$L$896,"<>보유중"),0) -> 0 | H42: =SUMIFS(거래내역!$N$2:$N$896,거래내역!$AF$2:$AF$896,$A42,거래내역!$L$2:$L$896,"<>보유중",거래내역!$A$2:$A$896,2024) -> 0 | I42: =SUMIFS(거래내역!$N$2:$N$896,거래내역!$AF$2:$AF$896,$A42,거래내역!$L$2:$L$896,"<>보유중",거래내역!$A$2:$A$896,2025) -> 0 | J42: =SUMIFS(거래내역!$N$2:$N$896,거래내역!$AF$2:$AF$896,$A42,거래내역!$L$2:$L$896,"<>보유중",거래내역!$A$2:$A$896,2026) -> 0
A43: 4) 5배 ~ 10배 | B43: =COUNTIFS(거래내역!$AF$2:$AF$896,A43,거래내역!$L$2:$L$896,"<>보유중") -> 0 | C43: =COUNTIFS(거래내역!$AF$2:$AF$896,A43,거래내역!$L$2:$L$896,"익절") -> 0 | D43: =COUNTIFS(거래내역!$AF$2:$AF$896,A43,거래내역!$L$2:$L$896,"손절") -> 0 | E43: =IFERROR(C43/(C43+D43),0) -> 0 | F43: =SUMIFS(거래내역!$N$2:$N$896,거래내역!$AF$2:$AF$896,A43,거래내역!$L$2:$L$896,"<>보유중") -> 0 | G43: =IFERROR(AVERAGEIFS(거래내역!$O$2:$O$896,거래내역!$AF$2:$AF$896,A43,거래내역!$L$2:$L$896,"<>보유중"),0) -> 0 | H43: =SUMIFS(거래내역!$N$2:$N$896,거래내역!$AF$2:$AF$896,$A43,거래내역!$L$2:$L$896,"<>보유중",거래내역!$A$2:$A$896,2024) -> 0 | I43: =SUMIFS(거래내역!$N$2:$N$896,거래내역!$AF$2:$AF$896,$A43,거래내역!$L$2:$L$896,"<>보유중",거래내역!$A$2:$A$896,2025) -> 0 | J43: =SUMIFS(거래내역!$N$2:$N$896,거래내역!$AF$2:$AF$896,$A43,거래내역!$L$2:$L$896,"<>보유중",거래내역!$A$2:$A$896,2026) -> 0
A44: 5) 10배 이상 | B44: =COUNTIFS(거래내역!$AF$2:$AF$896,A44,거래내역!$L$2:$L$896,"<>보유중") -> 189 | C44: =COUNTIFS(거래내역!$AF$2:$AF$896,A44,거래내역!$L$2:$L$896,"익절") -> 39 | D44: =COUNTIFS(거래내역!$AF$2:$AF$896,A44,거래내역!$L$2:$L$896,"손절") -> 150 | E44: =IFERROR(C44/(C44+D44),0) -> 0.20634921 | F44: =SUMIFS(거래내역!$N$2:$N$896,거래내역!$AF$2:$AF$896,A44,거래내역!$L$2:$L$896,"<>보유중") -> -21864 | G44: =IFERROR(AVERAGEIFS(거래내역!$O$2:$O$896,거래내역!$AF$2:$AF$896,A44,거래내역!$L$2:$L$896,"<>보유중"),0) -> 0.00011936433 | H44: =SUMIFS(거래내역!$N$2:$N$896,거래내역!$AF$2:$AF$896,$A44,거래내역!$L$2:$L$896,"<>보유중",거래내역!$A$2:$A$896,2024) -> -9630 | I44: =SUMIFS(거래내역!$N$2:$N$896,거래내역!$AF$2:$AF$896,$A44,거래내역!$L$2:$L$896,"<>보유중",거래내역!$A$2:$A$896,2025) -> 30389 | J44: =SUMIFS(거래내역!$N$2:$N$896,거래내역!$AF$2:$AF$896,$A44,거래내역!$L$2:$L$896,"<>보유중",거래내역!$A$2:$A$896,2026) -> -42623
A46: 매수일 캔들 (종가 vs 시가)
A47: 구분 | B47: 건수 | C47: 익절 | D47: 손절 | E47: 승률 | F47: 손익합(원) | G47: 평균 수익률 | H47: 2024 손익 | I47: 2025 손익 | J47: 2026 손익
...

Sheet 거래내역
A1: 연도 | B1: 매수월 | C1: 매수일(신호일) | D1: 요일 | E1: 종목코드 | F1: 종목명 | G1: 매수가 | H1: 수량 | I1: 매수금액 | J1: 매도일 | K1: 매도가 | L1: 결과 | M1: 보유일 | N1: 손익(원) | O1: 수익률 | P1: 보유중 최고 | Q1: 보유중 최저 | R1: 당일 상승률 | S1: 당일 거래대금(억) | T1: 20일 돌파폭 | U1: 20일평균 거래대금(억) | V1: 거래량 배수 | W1: 캔들 몸통(종/시) | X1: 윗꼬리(고/종) | Y1: 코스피 당일 | Z1: 코스피 5일 | AA1: 코스피 20일선 | AB1: 구간:코스피5일 | AC1: 구간:상승률 | AD1: 구간:거래대금 | AE1: 구간:돌파폭 | AF1: 구간:거래량배수 | AG1: 구간:캔들
A2: 2024 | B2: 2024-01 | C2: 45293 | D2: 화 | E2: 222800 | F2: 심텍 | G2: 42242 | H2: 2 | I2: 84484 | J2: 45294 | K2: 40210 | L2: 손절 | M2: 1 | N2: -4234 | O2: -0.050120385 | P2: 0.0013682999 | Q2: -0.04834502 | R2: 0.096103896 | S2: 87684805800 | T2: 0.087628866 | U2: 17067853480 | V2: 4.5781562 | W2: 0.094682231 | X2: 0.0047393365 | Y2: 0.0054721159 | Z2: 0.026842101 | AA2: 위 | AB2: 5일 상승 | AC2: 3) +5% ~ +10% | AD2: 3) 500억 ~ 1,000억 | AE2: 3) +5% ~ +10% | AF2: 3) 3배 ~ 5배 | AG2: 양봉
A3: 2024 | B3: 2024-01 | C3: 45293 | D3: 화 | E3: 094360 | F3: 칩스앤미디어 | G3: 34384 | H3: 2 | I3: 68769 | J3: 45294 | K3: 32717 | L3: 손절 | M3: 1 | N3: -3472 | O3: -0.050489723 | P3: 0.073162645 | Q3: -0.047531799 | R3: 0.078492936 | S3: 73617374250 | T3: 0.076802508 | U3: 5.1819363e+10 | V3: 1.2727388 | W3: 0.076802508 | X3: 0.0043668122 | Y3: 0.0054721159 | Z3: 0.026842101 | AA3: 위 | AB3: 5일 상승 | AC3: 3) +5% ~ +10% | AD3: 3) 500억 ~ 1,000억 | AE3: 3) +5% ~ +10% | AF3: 1) 2배 미만 | AG3: 양봉
A4: 2024 | B4: 2024-01 | C4: 45293 | D4: 화 | E4: 034220 | F4: LG디스플레이 | G4: 12352 | H4: 8 | I4: 98815 | J4: 45322 | K4: 11758 | L4: 손절 | M4: 21 | N4: -4947 | O4: -0.050066188 | P4: 0.09553368 | Q4: -0.093253911 | R4: 0.047880691 | S4: 35407724400 | T4: 0.018306636 | U4: 21400589342 | V4: 1.5378143 | W4: 0.047880691 | X4: 0.012734082 | Y4: 0.0054721159 | Z4: 0.026842101 | AA4: 위 | AB4: 5일 상승 | AC4: 2) +3% ~ +5% | AD4: 2) 300억 ~ 500억 | AE4: 1) +2% 미만 | AF4: 1) 2배 미만 | AG4: 양봉
A5: 2024 | B5: 2024-01 | C5: 45294 | D5: 수 | E5: 445180 | F5: 퓨릿 | G5: 13994 | H5: 7 | I5: 97958 | J5: 45295 | K5: 13317 | L5: 손절 | M5: 1 | N5: -4938 | O5: -0.050405718 | P5: -0.00314278 | Q5: -0.048876731 | R5: 0.23280423 | S5: 215546701620 | T5: 0.17974684 | U5: 3431905414 | V5: 50.602239 | W5: 0.214596 | X5: 0.054363376 | Y5: -0.023409906 | Z5: 0.0030005655 | AA5: 위 | AB5: 5일 상승 | AC5: 6) +20% 이상 | AD5: 5) 2,000억 이상 | AE5: 4) +10% 이상 | AF5: 5) 10배 이상 | AG5: 양봉
A6: 2024 | B6: 2024-01 | C6: 45294 | D6: 수 | E6: 065350 | F6: 신성델타테크 | G6: 43293 | H6: 2 | I6: 86586 | J6: 45295 | K6: 52000 | L6: 익절 | M6: 1 | N6: 17198 | O6: 0.19861886 | P6: 0.29812384 | Q6: -0.016012889 | R6: 0.040914561 | S6: 51222099500 | T6: 0.040914561 | U6: 5.778406e+10 | V6: 0.76844766 | W6: 0.039663462 | X6: 0.020809249 | Y6: -0.023409906 | Z6: 0.0030005655 | AA6: 위 | AB6: 5일 상승 | AC6: 2) +3% ~ +5% | AD6: 3) 500억 ~ 1,000억 | AE6: 2) +2% ~ +5% | AF6: 1) 2배 미만 | AG6: 양봉
A7: 2024 | B7: 2024-01 | C7: 45294 | D7: 수 | E7: 189300 | F7: 인텔리안테크 | G7: 81081 | H7: 1 | I7: 81081 | J7: 45296 | K7: 77123 | L7: 손절 | M7: 2 | N7: -4121 | O7: -0.050822654 | P7: 0.016267683 | Q7: -0.071299071 | R7: 0.078561917 | S7: 43903458000 | T7: 0.037131882 | U7: 6282555405 | V7: 6.3462762 | W7: 0.084337349 | X7: 0 | Y7: -0.023409906 | Z7: 0.0030005655 | AA7: 위 | AB7: 5일 상승 | AC7: 3) +5% ~ +10% | AD7: 2) 300억 ~ 500억 | AE7: 2) +2% ~ +5% | AF7: 4) 5배 ~ 10배 | AG7: 양봉
A8: 2024 | B8: 2024-01 | C8: 45294 | D8: 수 | E8: 182400 | F8: 엔케이젠바이오텍코리아 | G8: 13750 | H8: 7 | I8: 96253 | J8: 45295 | K8: 13087 | L8: 손절 | M8: 1 | N8: -4838 | O8: -0.050258708 | P8: 0.0043077772 | Q8: -0.051413394 | R8: 0.16203704 | S8: 40886394000 | T8: 0.11143911 | U8: 5170733909 | V8: 6.6095671 | W8: 0.15668203 | X8: 0.088977424 | Y8: -0.023409906 | Z8: 0.0030005655 | AA8: 위 | AB8: 5일 상승 | AC8: 5) +15% ~ +20% | AD8: 2) 300억 ~ 500억 | AE8: 4) +10% 이상 | AF8: 4) 5배 ~ 10배 | AG8: 양봉
A9: 2024 | B9: 2024-01 | C9: 45294 | D9: 수 | E9: 033100 | F9: 제룡전기 | G9: 22072 | H9: 4 | I9: 88288 | J9: 45320 | K9: 20979 | L9: 손절 | M9: 18 | N9: -4549 | O9: -0.051525339 | P9: 0.060164325 | Q9: -0.048570477 | R9: 0.080882353 | S9: 33862162950 | T9: 0.04009434 | U9: 5.0385537e+09 | V9: 6.1103282 | W9: 0.080882353 | X9: 0.0430839 | Y9: -0.023409906 | Z9: 0.0030005655 | AA9: 위 | AB9: 5일 상승 | AC9: 3) +5% ~ +10% | AD9: 2) 300억 ~ 500억 | AE9: 2) +2% ~ +5% | AF9: 4) 5배 ~ 10배 | AG9: 양봉
A10: 2024 | B10: 2024-01 | C10: 45294 | D10: 수 | E10: 336260 | F10: 두산퓨얼셀 | G10: 24524 | H10: 4 | I10: 98098 | J10: 45295 | K10: 23327 | L10: 손절 | M10: 1 | N10: -4988 | O10: -0.05084775 | P10: -0.0050765561 | Q10: -0.047890885 | R10: 0.044776119 | S10: 25746413000 | T10: 0.044776119 | U10: 7.8778312e+09 | V10: 2.9890405 | W10: 0.056034483 | X10: 0.020408163 | Y10: -0.023409906 | Z10: 0.0030005655 | AA10: 위 | AB10: 5일 상승 | AC10: 2) +3% ~ +5% | AD10: 1) 300억 미만 | AE10: 2) +2% ~ +5% | AF10: 2) 2배 ~ 3배 | AG10: 양봉
A11: 2024 | B11: 2024-01 | C11: 45295 | D11: 목 | E11: 047310 | F11: 파워로직스 | G11: 7638 | H11: 13 | I11: 99289 | J11: 45296 | K11: 7263 | L11: 손절 | M11: 1 | N11: -5073 | O11: -0.05109019 | P11: -0.000999001 | Q11: -0.073010869 | R11: 0.13204748 | S11: 60691026690 | T11: 0.13204748 | U11: 4.7817861e+09 | V11: 10.917199 | W11: 0.13541667 | X11: 0.076015727 | Y11: -0.0077819669 | Z11: -0.005982502 | AA11: 위 | AB11: 5일 하락 | AC11: 4) +10% ~ +15% | AD11: 3) 500억 ~ 1,000억 | AE11: 4) +10% 이상 | AF11: 5) 10배 이상 | AG11: 양봉
A12: 2024 | B12: 2024-01 | C12: 45295 | D12: 목 | E12: 110990 | F12: 디아이티 | G12: 21371 | H12: 4 | I12: 85485 | J12: 45296 | K12: 20330 | L12: 손절 | M12: 1 | N12: -4338 | O12: -0.050747778 | P12: -0.0033385818 | Q12: -0.064635599 | R12: 0.14784946 | S12: 47282222400 | T12: 0.031400966 | U12: 5914969461 | V12: 7.1432179 | W12: 0.15405405 | X12: 0.037470726 | Y12: -0.0077819669 | Z12: -0.005982502 | AA12: 위 | AB12: 5일 하락 | AC12: 4) +10% ~ +15% | AD12: 2) 300억 ~ 500억 | AE12: 2) +2% ~ +5% | AF12: 4) 5배 ~ 10배 | AG12: 양봉
A13: 2024 | B13: 2024-01 | C13: 45295 | D13: 목 | E13: 214680 | F13: 디알텍 | G13: 23073 | H13: 4 | I13: 92292 | J13: 45306 | K13: 21928 | L13: 손절 | M13: 7 | N13: -4765 | O13: -0.051628227 | P13: 0.10301846 | Q13: -0.076845064 | R13: 0.038288288 | S13: 45050233850 | T13: 0.024444444 | U13: 11957694916 | V13: 3.4438435 | W13: 0.022172949 | X13: 0.071583514 | Y13: -0.0077819669 | Z13: -0.005982502 | AA13: 위 | AB13: 5일 하락 | AC13: 2) +3% ~ +5% | AD13: 2) 300억 ~ 500억 | AE13: 2) +2% ~ +5% | AF13: 3) 3배 ~ 5배 | AG13: 양봉
... A173: 2024 | B173: 2024-06 | C173: 45464 | D173: 금 | E173: 017510 | F173: 세명전기 | G173: 5776 | H173: 17 | I173: 98188 | J173: 45468 | K173: 5435 | L173: 손절 | M173: 2 | N173: -5995 | O173: -0.061060907 | P173: 0.24831841 | Q173: -0.066791095 | R173: 0.11389961 | S173: 93478500600 | T173: 0.0052264808 | U173: 2.3239748e+10 | V173: 3.8306453 | W173: 0.11389961 | X173: 0.071057192 | Y173: -0.0083237464 | Z173: 0.0093676815 | AA173: 위 | AB173: 5일 상승 | AC173: 4) +10% ~ +15% | AD173: 3) 500억 ~ 1,000억 | AE173: 1) +2% 미만 | AF173: 3) 3배 ~ 5배 | AG173: 양봉
A174: 2024 | B174: 2024-06 | C174: 45464 | D174: 금 | E174: 017670 | F174: SK텔레콤 | G174: 52252 | H174: 1 | I174: 52252 | L174: 보유중 | M174: 128 | N174: 34648 | O174: 0.66691546 | P174: 1.669744 | Q174: -0.035447311 | R174: 0.01953125 | S174: 37809243000 | T174: 0.0038461538 | U174: 25437121490 | V174: 1.4618365 | W174: 0.01754386 | X174: 0 | Y174: -0.0083237464 | Z174: 0.0093676815 | AA174: 위 | AB174: 5일 상승 | AC174: 1) +3% 미만 | AD174: 2) 300억 ~ 500억 | AE174: 1) +2% 미만 | AF174: 1) 2배 미만 | AG174: 양봉
A175: 2024 | B175: 2024-06 | C175: 45467 | D175: 월 | E175: 017860 | F175: DS단석 | G175: 40990 | H175: 2 | I175: 81980 | J175: 45475 | K175: 39011 | L175: 손절 | M175: 6 | N175: -4123 | O175: -0.050291144 | P175: 0.15601011 | Q175: -0.066894018 | R175: 0.17511962 | S175: 132037752800 | T175: 0.10730388 | U175: 10681584115 | V175: 9.8990236 | W175: 0.17511962 | X175: 0.095276873 | Y175: -0.0070144311 | Z175: 0.0075179476 | AA175: 위 | AB175: 5일 상승 | AC175: 5) +15% ~ +20% | AD175: 4) 1,000억 ~ 2,000억 | AE175: 4) +10% 이상 | AF175: 4) 5배 ~ 10배 | AG175: 양봉
A176: 2024 | B176: 2024-06 | C176: 45468 | D176: 화 | E176: 028300 | F176: HLB | G176: 72873 | H176: 1 | I176: 72873 | J176: 45469 | K176: 69331 | L176: 손절 | M176: 1 | N176: -3688 | O176: -0.0506132 | P176: -0.0023712551 | Q176: -0.1656695 | R176: 0.1030303 | S176: 447991616800 | T176: 0.10136157 | U176: 240300965155 | V176: 1.5830769 | W176: 0.10136157 | X176: 0.013736264 | Y176: 0.0034940121 | Z176: 0.0037880981 | AA176: 위 | AB176: 5일 상승 | AC176: 4) +10% ~ +15% | AD176: 5) 2,000억 이상 | AE176: 4) +10% 이상 | AF176: 1) 2배 미만 | AG176: 양봉
A177: 2024 | B177: 2024-06 | C177: 45468 | D177: 화 | E177: 016360 | F177: 삼성증권 | G177: 38338 | H177: 2 | I177: 76677 | J177: 45490 | K177: 46050 | L177: 익절 | M177: 16 | N177: 15232 | O177: 0.19865648 | P177: 0.20375708 | Q177: -0.019257505 | R177: 0.018617021 | S177: 20152885500 | T177: 0.003931848 | U177: 3.4495629e+10 | V177: 0.55620409 | W177: 0.011889036 | X177: 0.0052219321 | Y177: 0.0034940121 | Z177: 0.0037880981 | AA177: 위 | AB177: 5일 상승 | AC177: 1) +3% 미만 | AD177: 1) 300억 미만 | AE177: 1) +2% 미만 | AF177: 1) 2배 미만 | AG177: 양봉
A178: 2024 | B178: 2024-06 | C178: 45469 | D178: 수 | E178: 095610 | F178: 테스 | G178: 26526 | H178: 3 | I178: 79579 | J178: 45475 | K178: 25225 | L178: 손절 | M178: 4 | N178: -4065 | O178: -0.051077874 | P178: 0.048008595 | Q178: -0.059431135 | R178: 0.18834081 | S178: 92721777500 | T178: 0.11111111 | U178: 6746299760 | V178: 12.05032 | W178: 0.18834081 | X178: 0.016981132 | Y178: 0.0063653632 | Z178: -0.0018875142 | AA178: 위 | AB178: 5일 하락 | AC178: 5) +15% ~ +20% | AD178: 3) 500억 ~ 1,000억 | AE178: 4) +10% 이상 | AF178: 5) 10배 이상 | AG178: 양봉
A179: 2024 | B179: 2024-06 | C179: 45469 | D179: 수 | E179: 078150 | F179: HB테크놀러지 | G179: 3609 | H179: 27 | I179: 97432 | J179: 45482 | K179: 4335 | L179: 익절 | M179: 9 | N179: 19370 | O179: 0.19880271 | P179: 0.29135774 | Q179: -0.041180733 | R179: 0.032951289 | S179: 25921222565 | T179: 0.01980198 | U179: 1.9121242e+10 | V179: 1.2283249 | W179: 0.02853067 | X179: 0.0083217753 | Y179: 0.0063653632 | Z179: -0.0018875142 | AA179: 위 | AB179: 5일 하락 | AC179: 2) +3% ~ +5% | AD179: 1) 300억 미만 | AE179: 1) +2% 미만 | AF179: 1) 2배 미만 | AG179: 양봉
A180: 2024 | B180: 2024-07 | C180: 45475 | D180: 화 | E180: 105560 | F180: KB금융 | G180: 83283 | H180: 1 | I180: 83283 | J180: 45509 | K180: 77323 | L180: 손절 | M180: 24 | N180: -6124 | O180: -0.073530695 | P180: 0.10946746 | Q180: -0.11146546 | R180: 0.045226131 | S180: 263257529600 | T180: 0.027160494 | U180: 85336391780 | V180: 2.9350592 | W180: 0.041301627 | X180: 0.021634615 | Y180: -0.0083621283 | Z180: 0.0023320442 | AA180: 위 | AB180: 5일 상승 | AC180: 2) +3% ~ +5% | AD180: 5) 2,000억 이상 | AE180: 2) +2% ~ +5% | AF180: 2) 2배 ~ 3배 | AG180: 양봉
A181: 2024 | B181: 2024-07 | C181: 45475 | D181: 화 | E181: 439580 | F181: 블루엠텍 | G181: 5171 | H181: 19 | I181: 98258 | J181: 45477 | K181: 4920 | L181: 손절 | M181: 2 | N181: -4974 | O181: -0.050619724 | P181: 0.064139218 | Q181: -0.055818294 | R181: 0.16729465 | S181: 249826515050 | T181: 0.13313826 | U181: 4.3096307e+09 | V181: 48.403755 | W181: 0.17526555 | X181: 0.05551969 | Y181: -0.0083621283 | Z181: 0.0023320442 | AA181: 위 | AB181: 5일 상승 | AC181: 5) +15% ~ +20% | AD181: 5) 2,000억 이상 | AE181: 4) +10% 이상 | AF181: 5) 10배 이상 | AG181: 양봉
A182: 2024 | B182: 2024-07 | C182: 45475 | D182: 화 | E182: 086790 | F182: 하나금융지주 | G182: 62963 | H182: 1 | I182: 62963 | J182: 45509 | K182: 59440 | L182: 손절 | M182: 24 | N182: -3648 | O182: -0.057934965 | P182: 0.076824606 | Q182: -0.11217558 | R182: 0.044850498 | S182: 86931448200 | T182: 0.0031897927 | U182: 38896343160 | V182: 2.1314203 | W182: 0.044850498 | X182: 0.0015898251 | Y182: -0.0083621283 | Z182: 0.0023320442 | AA182: 위 | AB182: 5일 상승 | AC182: 2) +3% ~ +5% | AD182: 3) 500억 ~ 1,000억 | AE182: 1) +2% 미만 | AF182: 2) 2배 ~ 3배 | AG182: 양봉
A183: 2024 | B183: 2024-07 | C183: 45477 | D183: 목 | E183: 335890 | F183: 비올 | G183: 11341 | H183: 8 | I183: 90731 | J183: 45483 | K183: 10689 | L183: 손절 | M183: 4 | N183: -5397 | O183: -0.059479385 | P183: 0.048377924 | Q183: -0.063601888 | R183: 0.072916667 | S183: 113479274590 | T183: 0.063849765 | U183: 18662522646 | V183: 5.5151772 | W183: 0.083173996 | X183: 0.012356575 | Y183: 0.011070111 | Z183: 0.014683592 | AA183: 위 | AB183: 5일 상승 | AC183: 3) +5% ~ +10% | AD183: 4) 1,000억 ~ 2,000억 | AE183: 3) +5% ~ +10% | AF183: 4) 5배 ~ 10배 | AG183: 양봉
A184: 2024 | B184: 2024-07 | C184: 45482 | D184: 화 | E184: 034020 | F184: 두산에너빌리티 | G184: 22272 | H184: 4 | I184: 89089 | J184: 45485 | K184: 20779 | L184: 손절 | M184: 3 | N184: -6148 | O184: -0.069005614 | P184: 0.0034908911 | Q184: -0.10336854 | R184: 0.05952381 | S184: 615706561250 | T184: 0.052009456 | U184: 147157803347 | V184: 3.8098955 | W184: 0.042154567 | X184: 0.002247191 | Y184: 0.0033662729 | Z184: 0.031112677 | AA184: 위 | AB184: 5일 상승 | AC184: 3) +5% ~ +10% | AD184: 5) 2,000억 이상 | AE184: 3) +5% ~ +10% | AF184: 3) 3배 ~ 5배 | AG184: 양봉
A185: 2024 | B185: 2024-07 | C185: 45483 | D185: 수 | E185: 251270 | F185: 넷마블 | G185: 58258 | H185: 1 | I185: 58258 | J185: 45513 | K185: 72000 | L185: 익절 | M185: 22 | N185: 13593 | O185: 0.23331756 | P185: 0.23759402 | Q185: -0.028462946 | R185: 0.024647887 | S185: 259364400600 | T185: 0.0034482759 | U185: 9052667040 | V185: 27.262048 | W185: 0.024647887 | X185: 0.015463918 | Y185: 0.00021273776 | Z185: 0.026478073 | AA185: 위 | AB185: 5일 상승 | AC185: 1) +3% 미만 | AD185: 5) 2,000억 이상 | AE185: 1) +2% 미만 | AF185: 5) 10배 이상 | AG185: 양봉
A186: 2024 | B186: 2024-07 | C186: 45483 | D186: 수 | E186: 010120 | F186: LS ELECTRIC | G186: 44945 | H186: 2 | I186: 89890 | J186: 45491 | K186: 42757 | L186: 손절 | M186: 6 | N186: -4556 | O186: -0.050680239 | P186: 0.05017477 | Q186: -0.07219729 | R186: 0.05399061 | S186: 241589164500 | T186: 0.01814059 | U186: 140138056975 | V186: 1.5634493 | W186: 0.041763341 | X186: 0.020044543 | Y186: 0.00021273776 | Z186: 0.026478073 | AA186: 위 | AB186: 5일 상승 | AC186: 3) +5% ~ +10% | AD186: 5) 2,000억 이상 | AE186: 1) +2% 미만 | AF186: 1) 2배 미만 | AG186: 양봉
... A315: 2024 | B315: 2024-12 | C315: 45639 | D315: 금 | E315: 010120 | F315: LS ELECTRIC | G315: 31491 | H315: 3 | I315: 94474 | J315: 45646 | K315: 29970 | L315: 손절 | M315: 5 | N315: -4754 | O315: -0.050319205 | P315: 0.032025825 | Q315: -0.053076612 | R315: 0.01483871 | S315: 37786763300 | T315: 0.0076873799 | U315: 42061504110 | V315: 0.83476314 | W315: 0.014184397 | X315: 0 | Y315: 0.0049715566 | Z315: 0.027304626 | AA315: 위 | AB315: 5일 상승 | AC315: 1) +3% 미만 | AD315: 2) 300억 ~ 500억 | AE315: 1) +2% 미만 | AF315: 1) 2배 미만 | AG315: 양봉
A316: 2024 | B316: 2024-12 | C316: 45639 | D316: 금 | E316: 103590 | F316: 일진전기 | G316: 25776 | H316: 3 | I316: 77327 | L316: 보유중 | M316: 10 | N316: 167222 | O316: 2.1696459 | P316: 4.7379514 | Q316: -0.23183613 | R316: 0.021825397 | S316: 29738700750 | T316: 0.017786561 | U316: 19569781650 | V316: 1.3458222 | W316: 0.021825397 | X316: 0.034951456 | Y316: 0.0049715566 | Z316: 0.027304626 | AA316: 위 | AB316: 5일 상승 | AC316: 1) +3% 미만 | AD316: 1) 300억 미만 | AE316: 1) +2% 미만 | AF316: 1) 2배 미만 | AG316: 양봉
A317: 2024 | B317: 2024-12 | C317: 45639 | D317: 금 | E317: 462870 | F317: 시프트업 | G317: 63163 | H317: 1 | I317: 63163 | J317: 45642 | K317: 60040 | L317: 손절 | M317: 1 | N317: -3250 | O317: -0.051450171 | P317: -0.0057486096 | Q317: -0.051661492 | R317: 0.12078153 | S317: 27264121800 | T317: 0.03442623 | U317: 7.3180435e+09 | V317: 3.2605071 | W317: 0.10896309 | X317: 0 | Y317: 0.0049715566 | Z317: 0.027304626 | AA317: 위 | AB317: 5일 상승 | AC317: 4) +10% ~ +15% | AD317: 1) 300억 미만 | AE317: 2) +2% ~ +5% | AF317: 3) 3배 ~ 5배 | AG317: 양봉
A318: 2024 | B318: 2024-12 | C318: 45639 | D318: 금 | E318: 166480 | F318: 코아스템켐온 | G318: 12291 | H318: 8 | I318: 98325 | J318: 45644 | K318: 8824 | L318: 손절 | M318: 3 | N318: -27888 | O318: -0.2836279 | P318: 0.08317866 | Q318: -0.28135931 | R318: 0.19766472 | S318: 21631774760 | T318: 0.12893082 | U318: 3.0019739e+09 | V318: 5.8786575 | W318: 0.18677686 | X318: 0.044568245 | Y318: 0.0049715566 | Z318: 0.027304626 | AA318: 위 | AB318: 5일 상승 | AC318: 5) +15% ~ +20% | AD318: 1) 300억 미만 | AE318: 4) +10% 이상 | AF318: 4) 5배 ~ 10배 | AG318: 양봉
A319: 2024 | B319: 2024-12 | C319: 45642 | D319: 월 | E319: 006340 | F319: 대원전선 | G319: 3213 | H319: 30 | I319: 96396 | J319: 45646 | K319: 3002 | L319: 손절 | M319: 4 | N319: -6527 | O319: -0.067705152 | P319: 0.18261801 | Q319: -0.11614865 | R319: 0.26627219 | S319: 143797214400 | T319: 0.15260323 | U319: 3.3282124e+09 | V319: 34.582234 | W319: 0.19109462 | X319: 0.026479751 | Y319: -0.0022008771 | Z319: 0.054389176 | AA319: 위 | AB319: 5일 상승 | AC319: 6) +20% 이상 | AD319: 4) 1,000억 ~ 2,000억 | AE319: 4) +10% 이상 | AF319: 5) 10배 이상 | AG319: 양봉
A320: 2024 | B320: 2024-12 | C320: 45642 | D320: 월 | E320: 001440 | F320: 대한전선 | G320: 12052 | H320: 8 | I320: 96416 | J320: 45645 | K320: 11419 | L320: 손절 | M320: 3 | N320: -5260 | O320: -0.054558732 | P320: 0.014765965 | Q320: -0.058250719 | R320: 0.044232437 | S320: 59395800240 | T320: 0.0083752094 | U320: 1.6606316e+10 | V320: 3.3607139 | W320: 0.029059829 | X320: 0.024916944 | Y320: -0.0022008771 | Z320: 0.054389176 | AA320: 위 | AB320: 5일 상승 | AC320: 2) +3% ~ +5% | AD320: 3) 500억 ~ 1,000억 | AE320: 1) +2% 미만 | AF320: 3) 3배 ~ 5배 | AG320: 양봉
A321: 2024 | B321: 2024-12 | C321: 45643 | D321: 화 | E321: 445090 | F321: 에이직랜드 | G321: 34885 | H321: 2 | I321: 69770 | J321: 45652 | K321: 33167 | L321: 손절 | M321: 6 | N321: -3576 | O321: -0.051253137 | P321: 0.16096242 | Q321: -0.054030618 | R321: 0.29074074 | S321: 161003410450 | T321: 0.22495606 | U321: 6448659195 | V321: 18.907278 | W321: 0.21640489 | X321: 0.0071736011 | Y321: -0.012921007 | Z321: 0.016117692 | AA321: 아래 | AB321: 5일 상승 | AC321: 6) +20% 이상 | AD321: 4) 1,000억 ~ 2,000억 | AE321: 4) +10% 이상 | AF321: 5) 10배 이상 | AG321: 양봉
A322: 2024 | B322: 2024-12 | C322: 45643 | D322: 화 | E322: 042700 | F322: 한미반도체 | G322: 86787 | H322: 1 | I322: 86787 | J322: 45645 | K322: 82118 | L322: 손절 | M322: 2 | N322: -4842 | O322: -0.055792509 | P322: 0.017437004 | Q322: -0.055154764 | R322: 0.034606205 | S322: 112413572700 | T322: 0.029691211 | U322: 53695733970 | V322: 1.9070343 | W322: 0.026035503 | X322: 0.026528258 | Y322: -0.012921007 | Z322: 0.016117692 | AA322: 아래 | AB322: 5일 상승 | AC322: 2) +3% ~ +5% | AD322: 4) 1,000억 ~ 2,000억 | AE322: 2) +2% ~ +5% | AF322: 1) 2배 미만 | AG322: 양봉
A323: 2024 | B323: 2024-12 | C323: 45644 | D323: 수 | E323: 321820 | F323: 아티스트컴퍼니 | G323: 20020 | H323: 4 | I323: 80080 | J323: 45645 | K323: 18931 | L323: 손절 | M323: 1 | N323: -4515 | O323: -0.05638704 | P323: 0.0064935065 | Q323: -0.075424575 | R323: 0.12044818 | S323: 98357560000 | T323: 0.082251082 | U323: 1.4838612e+10 | V323: 5.1757314 | W323: 0.11234705 | X323: 0.0675 | Y323: 0.011242221 | Z323: 0.017162673 | AA323: 위 | AB323: 5일 상승 | AC323: 4) +10% ~ +15% | AD323: 3) 500억 ~ 1,000억 | AE323: 3) +5% ~ +10% | AF323: 4) 5배 ~ 10배 | AG323: 양봉
A324: 2024 | B324: 2024-12 | C324: 45646 | D324: 금 | E324: 333430 | F324: 일승 | G324: 4595 | H324: 21 | I324: 96486 | J324: 45650 | K324: 4371 | L324: 손절 | M324: 2 | N324: -4897 | O324: -0.050750319 | P324: 0.049059873 | Q324: -0.060852002 | R324: 0.085106383 | S324: 152704558530 | T324: 0.026845638 | U324: 1.6701943e+10 | V324: 8.3748789 | W324: 0.06993007 | X324: 0.1416122 | Y324: -0.013046352 | Z324: -0.036204229 | AA324: 아래 | AB324: 5일 하락 | AC324: 3) +5% ~ +10% | AD324: 4) 1,000억 ~ 2,000억 | AE324: 2) +2% ~ +5% | AF324: 4) 5배 ~ 10배 | AG324: 양봉
A325: 2024 | B325: 2024-12 | C325: 45646 | D325: 금 | E325: 389470 | F325: 인벤티지랩 | G325: 17437 | H325: 5 | I325: 87187 | J325: 45656 | K325: 20950 | L325: 익절 | M325: 5 | N325: 17346 | O325: 0.1989464 | P325: 0.32186986 | Q325: -0.032540364 | R325: 0.14454665 | S325: 43283892080 | T325: 0.0040345821 | U325: 7.0272427e+09 | V325: 5.2930356 | W325: 0.12387097 | X325: 0.04075775 | Y325: -0.013046352 | Z325: -0.036204229 | AA325: 아래 | AB325: 5일 하락 | AC325: 4) +10% ~ +15% | AD325: 2) 300억 ~ 500억 | AE325: 1) +2% 미만 | AF325: 4) 5배 ~ 10배 | AG325: 양봉
A326: 2024 | B326: 2024-12 | C326: 45649 | D326: 월 | E326: 232140 | F326: 와이씨 | G326: 10741 | H326: 9 | I326: 96667 | J326: 45656 | K326: 10200 | L326: 손절 | M326: 4 | N326: -5062 | O326: -0.052365221 | P326: 0.019483778 | Q326: -0.062447338 | R326: 0.14882227 | S326: 50227505550 | T326: 0.021904762 | U326: 10696970661 | V326: 4.2127293 | W326: 0.1378579 | X326: 0.024231128 | Y326: 0.015747769 | Z326: -0.018867242 | AA326: 아래 | AB326: 5일 하락 | AC326: 4) +10% ~ +15% | AD326: 3) 500억 ~ 1,000억 | AE326: 2) +2% ~ +5% | AF326: 3) 3배 ~ 5배 | AG326: 양봉
A327: 2024 | B327: 2024-12 | C327: 45650 | D327: 화 | E327: 007660 | F327: 이수페타시스 | G327: 26966 | H327: 3 | I327: 80897 | L327: 보유중 | M327: 3 | N327: 275006 | O327: 3.409294 | P327: 5.0966185 | Q327: -0.096571299 | R327: 0.051233397 | S327: 227491568400 | T327: 0.035514019 | U327: 141549006750 | V327: 1.4434234 | W327: -0.028070175 | X327: 0.061371841 | Y327: -0.00061015311 | Z327: -0.0066305494 | AA327: 아래 | AB327: 5일 하락 | AC327: 3) +5% ~ +10% | AD327: 5) 2,000억 이상 | AE327: 2) +2% ~ +5% | AF327: 1) 2배 미만 | AG327: 음봉·보합
...

Sheet 놓친신호
A1: 연도 | B1: 매수월 | C1: 매수일(신호일) | D1: 요일 | E1: 종목코드 | F1: 종목명 | G1: 매수가 | H1: 수량 | I1: 매수금액 | J1: 매도일 | K1: 매도가 | L1: 결과 | M1: 보유일 | N1: 손익(원) | O1: 수익률 | P1: 보유중 최고 | Q1: 보유중 최저 | R1: 당일 상승률 | S1: 당일 거래대금(억) | T1: 20일 돌파폭 | U1: 20일평균 거래대금(억) | V1: 거래량 배수 | W1: 캔들 몸통(종/시) | X1: 윗꼬리(고/종) | Y1: 코스피 당일 | Z1: 코스피 5일 | AA1: 코스피 20일선 | AB1: 구간:코스피5일 | AC1: 구간:상승률 | AD1: 구간:거래대금 | AE1: 구간:돌파폭 | AF1: 구간:거래량배수 | AG1: 구간:캔들
A2: 2024 | B2: 2024-01 | C2: 45302 | D2: 목 | E2: 009410 | F2: 태영건설 | G2: 7538 | H2: 13 | I2: 97988 | J2: 45303 | K2: 7173 | L2: 손절 | M2: 1 | N2: -4938 | O2: -0.050391525 | P2: 0.070642505 | Q2: -0.19469641 | R2: 0.18769716 | S2: 126088630140 | T2: 0.072649573 | U2: 32680184768 | V2: 3.0696621 | W2: 0.083453237 | X2: 0.091633466 | Y2: -0.00067270396 | Z2: -0.018070985 | AA2: 아래 | AB2: 5일 하락 | AC2: 5) +15% ~ +20% | AD2: 4) 1,000억 ~ 2,000억 | AE2: 3) +5% ~ +10% | AF2: 3) 3배 ~ 5배 | AG2: 양봉
A3: 2024 | B3: 2024-01 | C3: 45302 | D3: 목 | E3: 214270 | F3: FSN | G3: 2783 | H3: 35 | I3: 97397 | J3: 45303 | K3: 2647 | L3: 손절 | M3: 1 | N3: -4935 | O3: -0.050672259 | P3: -0.0045925298 | Q3: -0.067479283 | R3: 0.049056604 | S3: 36054211980 | T3: 0.0054249548 | U3: 7.1017724e+09 | V3: 4.8852914 | W3: -0.0071428571 | X3: 0.10611511 | Y3: -0.00067270396 | Z3: -0.018070985 | AA3: 아래 | AB3: 5일 하락 | AC3: 2) +3% ~ +5% | AD3: 2) 300억 ~ 500억 | AE3: 1) +2% 미만 | AF3: 3) 3배 ~ 5배 | AG3: 음봉·보합
A4: 2024 | B4: 2024-01 | C4: 45302 | D4: 목 | E4: 025980 | F4: 아난티 | G4: 6817 | H4: 14 | I4: 95435 | J4: 45315 | K4: 6484 | L4: 손절 | M4: 9 | N4: -4858 | O4: -0.050898494 | P4: 0.016604541 | Q4: -0.090483672 | R4: 0.03652968 | S4: 24215079720 | T4: 0.0014705882 | U4: 4.3120381e+09 | V4: 5.4008883 | W4: 0.027149321 | X4: 0.027900147 | Y4: -0.00067270396 | Z4: -0.018070985 | AA4: 아래 | AB4: 5일 하락 | AC4: 2) +3% ~ +5% | AD4: 1) 300억 미만 | AE4: 1) +2% 미만 | AF4: 4) 5배 ~ 10배 | AG4: 양봉
A5: 2024 | B5: 2024-01 | C5: 45302 | D5: 목 | E5: 293490 | F5: 카카오게임즈 | G5: 27227 | H5: 3 | I5: 81682 | J5: 45307 | K5: 25874 | L5: 손절 | M5: 3 | N5: -4223 | O5: -0.051699718 | P5: 0.017364988 | Q5: -0.056090968 | R5: 0.036190476 | S5: 23735073600 | T5: 0.014925373 | U5: 7.1794385e+09 | V5: 3.1601156 | W5: 0.026415094 | X5: 0.014705882 | Y5: -0.00067270396 | Z5: -0.018070985 | AA5: 아래 | AB5: 5일 하락 | AC5: 2) +3% ~ +5% | AD5: 1) 300억 미만 | AE5: 1) +2% 미만 | AF5: 3) 3배 ~ 5배 | AG5: 양봉
A6: 2024 | B6: 2024-01 | C6: 45316 | D6: 목 | E6: 066790 | F6: 씨씨에스 | G6: 3356 | H6: 29 | I6: 97321 | J6: 45317 | K6: 2921 | L6: 손절 | M6: 1 | N6: -12782 | O6: -0.13134354 | P6: -0.051609184 | Q6: -0.12862468 | R6: 0.022522523 | S6: 44556910650 | T6: 0.01793722 | U6: 2.0797585e+10 | V6: 1.9973314 | W6: 0.0657277 | X6: 0.081497797 | Y6: 0.00026319093 | Z6: 0.012417829 | AA6: 아래 | AB6: 5일 상승 | AC6: 1) +3% 미만 | AD6: 2) 300억 ~ 500억 | AE6: 1) +2% 미만 | AF6: 1) 2배 미만 | AG6: 양봉
A7: 2024 | B7: 2024-01 | C7: 45320 | D7: 월 | E7: 267270 | F7: HD건설기계 | G7: 53553 | H7: 1 | I7: 53553 | J7: 45321 | K7: 50949 | L7: 손절 | M7: 1 | N7: -2712 | O7: -0.050638774 | P7: 0.027010373 | Q7: -0.055150457 | R7: 0.055226824 | S7: 41149257500 | T7: 0.034816248 | U7: 9977277715 | V7: 3.7416637 | W7: 0.049019608 | X7: 0.013084112 | Y7: 0.008912433 | Z7: 0.014730051 | AA7: 아래 | AB7: 5일 상승 | AC7: 3) +5% ~ +10% | AD7: 2) 300억 ~ 500억 | AE7: 2) +2% ~ +5% | AF7: 3) 3배 ~ 5배 | AG7: 양봉
A8: 2024 | B8: 2024-01 | C8: 45320 | D8: 월 | E8: 023530 | F8: 롯데쇼핑 | G8: 79479 | H8: 1 | I8: 79479 | J8: 45348 | K8: 75624 | L8: 손절 | M8: 18 | N8: -4014 | O8: -0.050509809 | P8: 0.15879083 | Q8: -0.048810132 | R8: 0.086183311 | S8: 23285082200 | T8: 0.058666667 | U8: 4194334350 | V8: 4.9832921 | W8: 0.075880759 | X8: 0.0088161209 | Y8: 0.008912433 | Z8: 0.014730051 | AA8: 아래 | AB8: 5일 상승 | AC8: 3) +5% ~ +10% | AD8: 1) 300억 미만 | AE8: 3) +5% ~ +10% | AF8: 3) 3배 ~ 5배 | AG8: 양봉
A9: 2024 | B9: 2024-01 | C9: 45321 | D9: 화 | E9: 004990 | F9: 롯데지주 | G9: 28328 | H9: 3 | I9: 84985 | J9: 45383 | K9: 26923 | L9: 손절 | M9: 41 | N9: -4386 | O9: -0.05160914 | P9: 0.19138812 | Q9: -0.048654526 | R9: 0.055970149 | S9: 23739398400 | T9: 0.055970149 | U9: 3142046850 | V9: 6.8042968 | W9: 0.042357274 | X9: 0.024734982 | Y9: -0.00073580869 | Z9: 0.0081497291 | AA9: 아래 | AB9: 5일 상승 | AC9: 3) +5% ~ +10% | AD9: 1) 300억 미만 | AE9: 3) +5% ~ +10% | AF9: 4) 5배 ~ 10배 | AG9: 양봉
A10: 2024 | B10: 2024-01 | C10: 45321 | D10: 화 | E10: 069960 | F10: 현대백화점 | G10: 52452 | H10: 1 | I10: 52452 | J10: 45370 | K10: 49900 | L10: 손절 | M10: 32 | N10: -2658 | O10: -0.050665422 | P10: 0.18011759 | Q10: -0.049614508 | R10: 0.0234375 | S10: 22578793200 | T10: 0.017475728 | U10: 4208753995 | V10: 5.0037073 | W10: 0.0096339114 | X10: 0.020992366 | Y10: -0.00073580869 | Z10: 0.0081497291 | AA10: 아래 | AB10: 5일 상승 | AC10: 1) +3% 미만 | AD10: 1) 300억 미만 | AE10: 1) +2% 미만 | AF10: 4) 5배 ~ 10배 | AG10: 양봉
A11: 2024 | B11: 2024-01 | C11: 45322 | D11: 수 | E11: 032640 | F11: LG유플러스 | G11: 10240 | H11: 9 | I11: 92162 | J11: 45390 | K11: 9740 | L11: 손절 | M11: 45 | N11: -4685 | O11: -0.050829866 | P11: 0.025367594 | Q11: -0.047872948 | R11: 0.0068897638 | S11: 51011352810 | T11: 0.0068897638 | U11: 7.8020763e+09 | V11: 6.3702094 | W11: 0.010869565 | X11: 0 | Y11: -0.00068832764 | Z11: 0.01109451 | AA11: 아래 | AB11: 5일 상승 | AC11: 1) +3% 미만 | AD11: 3) 500억 ~ 1,000억 | AE11: 1) +2% 미만 | AF11: 4) 5배 ~ 10배 | AG11: 양봉
A12: 2024 | B12: 2024-01 | C12: 45322 | D12: 수 | E12: 032830 | F12: 삼성생명 | G12: 69369 | H12: 1 | I12: 69369 | J12: 45330 | K12: 83300 | L12: 익절 | M12: 6 | N12: 13758 | O12: 0.19832778 | P12: 0.20226094 | Q12: -0.0067652405 | R12: 0.053191489 | S12: 47368005300 | T12: 0.034328358 | U12: 25388591195 | V12: 1.7029117 | W12: 0.053191489 | X12: 0 | Y12: -0.00068832764 | Z12: 0.01109451 | AA12: 아래 | AB12: 5일 상승 | AC12: 3) +5% ~ +10% | AD12: 2) 300억 ~ 500억 | AE12: 2) +2% ~ +5% | AF12: 1) 2배 미만 | AG12: 양봉
A13: 2024 | B13: 2024-01 | C13: 45322 | D13: 수 | E13: 241560 | F13: 두산밥캣 | G13: 50951 | H13: 1 | I13: 50951 | J13: 45323 | K13: 48501 | L13: 손절 | M13: 1 | N13: -2552 | O13: -0.050080969 | P13: -0.0049243487 | Q13: -0.060860554 | R13: 0.087606838 | S13: 27846982800 | T13: 0.082978723 | U13: 9.997516e+09 | V13: 2.5000291 | W13: 0.077248677 | X13: 0.0019646365 | Y13: -0.00068832764 | Z13: 0.01109451 | AA13: 아래 | AB13: 5일 상승 | AC13: 3) +5% ~ +10% | AD13: 1) 300억 미만 | AE13: 3) +5% ~ +10% | AF13: 2) 2배 ~ 3배 | AG13: 양봉
... A168: 2024 | B168: 2024-05 | C168: 45422 | D168: 금 | E168: 006880 | F168: 신송홀딩스 | G168: 8458 | H168: 11 | I168: 93043 | J168: 45453 | K168: 8052 | L168: 손절 | M168: 19 | N168: -4658 | O168: -0.050065916 | P168: 0.1940722 | Q168: -0.048288989 | R168: 0.048387097 | S168: 34332721800 | T168: 0.018072289 | U168: 4464272818 | V168: 6.9692198 | W168: -0.092373792 | X168: 0.12307692 | Y168: 0.0057113571 | Z168: 0.016388128 | AA168: 위 | AB168: 5일 상승 | AC168: 2) +3% ~ +5% | AD168: 2) 300억 ~ 500억 | AE168: 1) +2% 미만 | AF168: 4) 5배 ~ 10배 | AG168: 음봉·보합
A169: 2024 | B169: 2024-05 | C169: 45422 | D169: 금 | E169: 017670 | F169: SK텔레콤 | G169: 52452 | H169: 1 | I169: 52452 | L169: 보유중 | M169: 156 | N169: 34448 | O169: 0.66055319 | P169: 1.6595542 | Q169: -0.03912881 | R169: 0.011583012 | S169: 23263661200 | T169: 0.011583012 | U169: 19654083305 | V169: 1.1522139 | W169: 0.0057581574 | X169: 0.0076335878 | Y169: 0.0057113571 | Z169: 0.016388128 | AA169: 위 | AB169: 5일 상승 | AC169: 1) +3% 미만 | AD169: 1) 300억 미만 | AE169: 1) +2% 미만 | AF169: 1) 2배 미만 | AG169: 양봉
